Workbook

Sheet EDM自动
A1: 加工计划 | O1: 铜-钢 | P1: 通用 | Q1: 铜-钢 | R1: 通用 | S1: 1 | T1: C0 | V1: =IF(X1>0,"VDI"&W1&"-"&"Ra"&X1,"") -> VDI14-Ra0.5 | W1: {=INDEX(Y:Y,_xlfn.XMATCH(X1,Z:Z,0),0)} -> 14 | X1: {=_xlfn._xlws.SORT(_xlfn.UNIQUE(BM:BM))} -> 0.5 | Y1: 0 | Z1: 0.07 | AB1: ="□"&ROUND(SQRT(3.14*(AC1/2)^2),0)&"○"&AC1 -> □1○1 | AC1: {=_xlfn._xlws.SORT(_xlfn.UNIQUE(INDIRECT("'"&EDM自动!$B$3&"'!AD2:AD99999")))} -> 1 | AE1: 无 | AF1: 0000 | AH1: {=_xlfn._xlws.FILTER(INDIRECT("'"&EDM自动!$B$3&"'!B:AH"),(INDIRECT("'"&EDM自动!$B$3&"'!AD:AD")=EDM自动!$G$6))} -> 9 | AI1: 300 | AJ1: 55 | AK1: 0 | AL1: 135 | AM1: 50 | AN1: 15 | AO1: 15 | AP1: 180 | AQ1: 03 | AR1: 31 | AS1: 0 | AT1: 0 | AU1: 1 | AV1: 0 | AW1: + | AX1: 21 | AY1: 10 | AZ1: 3 | BA1: 1502 | BB1: 0.274 | BC1: 0.2411 | BD1: 24 | BE1: 0 | BF1: T | BG1: 0 | BH1: 0 | BI1: 1 | BJ1: 90 | BK1: 1 | BL1: 1 | BM1: 0.5 | BN1: 0
A2: 材料组合 | B2: 铜-钢 | G2: =_xlfn.XMATCH(B2,O1:O8,0) -> 1 | O2: 石墨-钢 | P2: 深腔 | Q2: 铜-钢 | R2: 深腔 | S2: 2 | T2: C0 | V2: =IF(X2>0,"VDI"&W2&"-"&"Ra"&X2,"") -> VDI16-Ra0.63 | W2: {=INDEX(Y:Y,_xlfn.XMATCH(X2,Z:Z,0),0)} -> 16 | X2: 0.63 | Y2: 0 | Z2: 0.1 | AB2: ="□"&ROUND(SQRT(3.14*(AC2/2)^2),0)&"○"&AC2 -> □3○3 | AC2: 3 | AE2: 圆 | AF2: 1111 | AH2: 8 | AI2: 200 | AJ2: 40 | AK2: 0 | AL2: 85 | AM2: 50 | AN2: 15 | AO2: 15 | AP2: 180 | AQ2: 03 | AR2: 32 | AS2: 0 | AT2: 0 | AU2: 1 | AV2: 0 | AW2: + | AX2: 31 | AY2: 15 | AZ2: 4 | BA2: 1502 | BB2: 0.18 | BC2: 0.1638 | BD2: 24 | BE2: 0 | BF2: T | BG2: 0 | BH2: 0 | BI2: 1 | BJ2: 90 | BK2: 1 | BL2: 1 | BM2: 0.5 | BN2: 0
A3: 电极形状 | B3: 通用 | C3: 用于选取参数表 | G3: =_xlfn.XMATCH(B3,P1:P10,0) -> 1 | O3: 铜-钨钢 | P3: 大面积 | Q3: 铜-钢 | R3: 大面积 | S3: 3 | T3: C0 | V3: =IF(X3>0,"VDI"&W3&"-"&"Ra"&X3,"") -> VDI18-Ra0.8 | W3: {=INDEX(Y:Y,_xlfn.XMATCH(X3,Z:Z,0),0)} -> 18 | X3: 0.8 | Y3: 1 | Z3: 0.112 | AB3: ="□"&ROUND(SQRT(3.14*(AC3/2)^2),0)&"○"&AC3 -> □5○6 | AC3: 6 | AE3: 方 | AF3: 2222 | AH3: 7 | AI3: 140 | AJ3: 40 | AK3: 0 | AL3: 53 | AM3: 60 | AN3: 15 | AO3: 15 | AP3: 180 | AQ3: 03 | AR3: 53 | AS3: 0 | AT3: 40 | AU3: 0 | AV3: 0 | AW3: + | AX3: 31 | AY3: 15 | AZ3: 4 | BA3: 1202 | BB3: 0.125 | BC3: 0.115 | BD3: 24 | BE3: 0 | BF3: T | BG3: 0 | BH3: 0 | BI3: 1 | BJ3: 90 | BK3: 1 | BL3: 1 | BM3: 0.5 | BN3: 0
A4: 加工方向 | B4: Z+ | C4: 用于判断余量方向，非Z轴加工时，抬刀速度除4高度除2 | G4: =IF(OR(B4="Z-",B4="Z-"),0,1) -> 1 | O4: 铜-铜 | P4: 骨位 | Q4: 铜-钢 | R4: 骨位 | S4: 4 | T4: C0 | V4: =IF(X4>0,"VDI"&W4&"-"&"Ra"&X4,"") -> VDI21-Ra1.12 | W4: {=INDEX(Y:Y,_xlfn.XMATCH(X4,Z:Z,0),0)} -> 21 | X4: 1.12 | Y4: 2 | Z4: 0.126 | AB4: ="□"&ROUND(SQRT(3.14*(AC4/2)^2),0)&"○"&AC4 -> □7○8 | AC4: 8 | AE4: 菱形 | AF4: 3333 | AH4: 6 | AI4: 70 | AJ4: 25 | AK4: 0 | AL4: 33 | AM4: 60 | AN4: 15 | AO4: 15 | AP4: 180 | AQ4: 03 | AR4: 73 | AS4: 0 | AT4: 40 | AU4: 0 | AV4: 0 | AW4: + | AX4: 31 | AY4: 15 | AZ4: 4 | BA4: 1202 | BB4: 0.082 | BC4: 0.0763 | BD4: 24 | BE4: 0 | BF4: T | BG4: 0 | BH4: 4 | BI4: 1 | BJ4: 90 | BK4: 1 | BL4: 1 | BM4: 0.5 | BN4: 0
A5: 加工深度 | B5: -0.1 | O5: 铜-铝 | P5: 插件 | Q5: 铜-钢 | R5: 插件 | S5: 5 | T5: C0 | V5: =IF(X5>0,"VDI"&W5&"-"&"Ra"&X5,"") -> VDI24-Ra1.6 | W5: {=INDEX(Y:Y,_xlfn.XMATCH(X5,Z:Z,0),0)} -> 24 | X5: 1.6 | Y5: 3 | Z5: 0.14 | AB5: ="□"&ROUND(SQRT(3.14*(AC5/2)^2),0)&"○"&AC5 -> □10○11 | AC5: 11 | AE5: 交叉 | AF5: 4444 | AH5: 5 | AI5: 40 | AJ5: 20 | AK5: 0 | AL5: 23 | AM5: 70 | AN5: 15 | AO5: 18 | AP5: 180 | AQ5: 00 | AR5: 73 | AS5: 0 | AT5: 40 | AU5: 0 | AV5: 0 | AW5: + | AX5: 31 | AY5: 15 | AZ5: 4 | BA5: 2202 | BB5: 0.052 | BC5: 0.052 | BD5: 24 | BE5: 0 | BF5: T | BG5: 0 | BH5: 2.8 | BI5: 1 | BJ5: 90 | BK5: 1 | BL5: 1 | BM5: 0.5 | BN5: 0
A6: 加工面积 | B6: □80○90 | C6: AC1:列通过电极形状确定参数表后，从参数表面积一列调取唯一值到AC列，用于下拉选择，避免空数据库 | G6: {=INDEX(AB:AC,_xlfn.XMATCH(B6,AB:AB,0),2)} -> 90 | O6: 石墨-铝 | P6: 多脚 | Q6: 铜-钢 | R6: 多脚 | S6: 6 | T6: C0 | V6: =IF(X6>0,"VDI"&W6&"-"&"Ra"&X6,"") -> VDI26-Ra2 | W6: {=INDEX(Y:Y,_xlfn.XMATCH(X6,Z:Z,0),0)} -> 26 | X6: 2 | Y6: 4 | Z6: 0.16 | AB6: ="□"&ROUND(SQRT(3.14*(AC6/2)^2),0)&"○"&AC6 -> □13○15 | AC6: 15 | AE6: 十字 | AF6: 5555 | AH6: 4 | AI6: 10 | AJ6: 9 | AK6: 0 | AL6: 15 | AM6: 80 | AN6: 15 | AO6: 18 | AP6: 180 | AQ6: 00 | AR6: 73 | AS6: 0 | AT6: 40 | AU6: 0 | AV6: 0 | AW6: + | AX6: 31 | AY6: 15 | AZ6: 5 | BA6: 2202 | BB6: 0.03 | BC6: 0.033 | BD6: 24 | BE6: 0 | BF6: T | BG6: 0 | BH6: 2 | BI6: 1 | BJ6: 90 | BK6: 1 | BL6: 1 | BM6: 0.5 | BN6: 0
A7: 参考深度 | O7: 钢-铍铜 | P7: 螺牙 | Q7: 铜-钢 | R7: 螺牙 | S7: 7 | T7: C0 | V7: =IF(X7>0,"VDI"&W7&"-"&"Ra"&X7,"") -> VDI29-Ra2.8 | W7: {=INDEX(Y:Y,_xlfn.XMATCH(X7,Z:Z,0),0)} -> 29 | X7: 2.8 | Y7: 5 | Z7: 0.18 | AB7: ="□"&ROUND(SQRT(3.14*(AC7/2)^2),0)&"○"&AC7 -> □15○17 | AC7: 17 | AE7: 象限 | AF7: 6666 | AH7: 3 | AI7: 7 | AJ7: 9 | AK7: 0 | AL7: 8 | AM7: 95 | AN7: 15 | AO7: 20 | AP7: 180 | AQ7: 00 | AR7: 73 | AS7: 0 | AT7: 0 | AU7: 0 | AV7: 0 | AW7: + | AX7: 31 | AY7: 15 | AZ7: 5 | BA7: 2202 | BB7: 0.018 | BC7: 0.023 | BD7: 24 | BE7: 0 | BF7: T | BG7: 0 | BH7: 1.12 | BI7: 1 | BJ7: 90 | BK7: 1 | BL7: 1 | BM7: 0.5 | BN7: 0
A8: 粗糙度 | B8: VDI16-Ra0.63 | C8: AH1:先通过电极形状和加工面积调取整组参数，再从整组参数BM列调取唯一值到X列，用于下拉选择，避免空数据库 | G8: {=INDEX(V1:X47,_xlfn.XMATCH(B8,V:V,0),3)} -> 0.63 | O8: 石墨-铍铜 | P8: 蜗杆 | Q8: 铜-钢 | R8: 蜗杆 | S8: 8 | T8: C0 | V8: =IF(X8>0,"VDI"&W8&"-"&"Ra"&X8,"") -> VDI31-Ra3.5 | W8: {=INDEX(Y:Y,_xlfn.XMATCH(X8,Z:Z,0),0)} -> 31 | X8: 3.5 | Y8: 6 | Z8: 0.2 | AB8: ="□"&ROUND(SQRT(3.14*(AC8/2)^2),0)&"○"&AC8 -> □17○19 | AC8: 19 | AH8: 802 | AI8: 1 | AJ8: 9 | AK8: 0 | AL8: 15 | AM8: 110 | AN8: 15 | AO8: 20 | AP8: 180 | AQ8: 00 | AR8: 73 | AS8: 0 | AT8: 0 | AU8: 10 | AV8: 3 | AW8: - | AX8: 32 | AY8: 30 | AZ8: 5 | BA8: 2202 | BB8: -0.007 | BC8: 0.026 | BD8: 24 | BE8: 0.6 | BF8: Z | BG8: 10400 | BH8: 0.63 | BI8: 1 | BJ8: 90 | BK8: 1 | BL8: 1 | BM8: 0.5 | BN8: 0
A9: 摇动形状 | B9: 分象限 | C9: {="LP="&IF(B9="分象限",E9&D9&D10&E10,INDEX(AE1:AF7,_xlfn.XMATCH(B9,AE1:AE7,0),2))} -> LP=1234 | D9: 2 | E9: 1 | F9: 当摇动形状选择分象限时，LP的每个象限可以单独编辑输入 | P9: 清角 | Q9: 铜-钢 | R9: 清角 | S9: 9 | T9: C0 | V9: =IF(X9>0,"VDI"&W9&"-"&"Ra"&X9,"") -> VDI32-Ra4 | W9: {=INDEX(Y:Y,_xlfn.XMATCH(X9,Z:Z,0),0)} -> 32 | X9: 4 | Y9: 7 | Z9: 0.22 | AB9: ="□"&ROUND(SQRT(3.14*(AC9/2)^2),0)&"○"&AC9 -> □20○23 | AC9: 23 | AH9: 802 | AI9: 1 | AJ9: 9 | AK9: 0 | AL9: 15 | AM9: 110 | AN9: 15 | AO9: 20 | AP9: 180 | AQ9: 00 | AR9: 73 | AS9: 0 | AT9: 0 | AU9: 10 | AV9: 3 | AW9: - | AX9: 32 | AY9: 30 | AZ9: 5 | BA9: 2202 | BB9: 0.013 | BC9: 0.0111 | BD9: 24 | BE9: 0.6 | BF9: Z | BG9: 312 | BH9: 0.63 | BI9: 1 | BJ9: 90 | BK9: 1 | BL9: 1 | BM9: 0.5 | BN9: 0
A10: 摇动模式 | B10: 思考 | D10: 3 | E10: 4 | G10: =IF(B10="自由",0,IF(B10="锁定",200,IF(B10="思考",300,0))) -> 300 | P10: 进胶口 | Q10: 铜-钢 | R10: 进胶口 | S10: 10 | T10: C0 | V10: =IF(X10>0,"VDI"&W10&"-"&"Ra"&X10,"") -> VDI33-Ra4.5 | W10: {=INDEX(Y:Y,_xlfn.XMATCH(X10,Z:Z,0),0)} -> 33 | X10: 4.5 | Y10: 8 | Z10: 0.25 | AB10: ="□"&ROUND(SQRT(3.14*(AC10/2)^2),0)&"○"&AC10 -> □25○28 | AC10: 28 | AH10: 801 | AI10: 1 | AJ10: 9 | AK10: 0 | AL10: 15 | AM10: 110 | AN10: 15 | AO10: 20 | AP10: 180 | AQ10: 00 | AR10: 73 | AS10: 0 | AT10: 40 | AU10: 10 | AV10: 2 | AW10: - | AX10: 32 | AY10: 30 | AZ10: 5 | BA10: 3202 | BB10: -0.01 | BC10: 0.023 | BD10: 24 | BE10: 1.2 | BF10: Z | BG10: 20800 | BH10: 0.5 | BI10: 1 | BJ10: 90 | BK10: 1 | BL10: 1 | BM10: 0.5 | BN10: 0
A11: 加工侧重 | B11: 标准 | G11: =IF(B11="标准",1,IF(B11="低损耗",2,3)) -> 1 | H11: {=IF(A18<=$B$16,"",$N$18:$N$35)} | Q11: 石墨-钢 | R11: 通用 | S11: 11 | T11: C4 | V11: =IF(X11>0,"VDI"&W11&"-"&"Ra"&X11,"") | W11: {=INDEX(Y:Y,_xlfn.XMATCH(X11,Z:Z,0),0)} -> 0 | X11: 0 | Y11: 9 | Z11: 0.28 | AB11: ="□"&ROUND(SQRT(3.14*(AC11/2)^2),0)&"○"&AC11 -> □30○34 | AC11: 34 | AH11: 801 | AI11: 1 | AJ11: 9 | AK11: 0 | AL11: 15 | AM11: 110 | AN11: 15 | AO11: 20 | AP11: 180 | AQ11: 00 | AR11: 73 | AS11: 0 | AT11: 40 | AU11: 10 | AV11: 2 | AW11: - | AX11: 32 | AY11: 30 | AZ11: 5 | BA11: 3202 | BB11: 0.01 | BC11: 0.008 | BD11: 24 | BE11: 1.2 | BF11: Z | BG11: 624 | BH11: 0.5 | BI11: 1 | BJ11: 90 | BK11: 1 | BL11: 1 | BM11: 0.5 | BN11: 0
A12: 单边火花位 | B12: 0.1 | C12: 输入范围(0.04~0.50) | Q12: 石墨-钢 | R12: 深腔 | S12: 12 | T12: C4 | V12: =IF(X12>0,"VDI"&W12&"-"&"Ra"&X12,"") | W12: {=INDEX(Y:Y,_xlfn.XMATCH(X12,Z:Z,0),0)} -> 0 | Y12: 10 | Z12: 0.32 | AB12: ="□"&ROUND(SQRT(3.14*(AC12/2)^2),0)&"○"&AC12 -> □35○39 | AC12: 39 | AH12: 8 | AI12: 300 | AJ12: 55 | AK12: 0 | AL12: 135 | AM12: 50 | AN12: 15 | AO12: 15 | AP12: 180 | AQ12: 03 | AR12: 31 | AS12: 0 | AT12: 0 | AU12: 1 | AV12: 0 | AW12: + | AX12: 21 | AY12: 10 | AZ12: 3 | BA12: 1502 | BB12: 0.274 | BC12: 0.2411 | BD12: 24 | BE12: 0 | BF12: T | BG12: 0 | BH12: 0 | BI12: 1 | BJ12: 90 | BK12: 1 | BL12: 1 | BM12: 0.63 | BN12: 0
Q13: 石墨-钢 | R13: 大面积 | S13: 13 | T13: C4 | V13: =IF(X13>0,"VDI"&W13&"-"&"Ra"&X13,"") | W13: {=INDEX(Y:Y,_xlfn.XMATCH(X13,Z:Z,0),0)} -> 0 | Y13: 11 | Z13: 0.35 | AB13: ="□"&ROUND(SQRT(3.14*(AC13/2)^2),0)&"○"&AC13 -> □40○45 | AC13: 45 | AH13: 7 | AI13: 200 | AJ13: 40 | AK13: 0 | AL13: 85 | AM13: 50 | AN13: 15 | AO13: 15 | AP13: 180 | AQ13: 03 | AR13: 32 | AS13: 0 | AT13: 0 | AU13: 1 | AV13: 0 | AW13: + | AX13: 31 | AY13: 15 | AZ13: 4 | BA13: 1502 | BB13: 0.18 | BC13: 0.1638 | BD13: 24 | BE13: 0 | BF13: T | BG13: 0 | BH13: 0 | BI13: 1 | BJ13: 90 | BK13: 1 | BL13: 1 | BM13: 0.63 | BN13: 0
Q14: 石墨-钢 | R14: 骨位 | S14: 14 | T14: C4 | V14: =IF(X14>0,"VDI"&W14&"-"&"Ra"&X14,"") | W14: {=INDEX(Y:Y,_xlfn.XMATCH(X14,Z:Z,0),0)} -> 0 | Y14: 12 | Z14: 0.4 | AB14: ="□"&ROUND(SQRT(3.14*(AC14/2)^2),0)&"○"&AC14 -> □45○51 | AC14: 51 | AH14: 6 | AI14: 140 | AJ14: 40 | AK14: 0 | AL14: 53 | AM14: 60 | AN14: 15 | AO14: 15 | AP14: 180 | AQ14: 03 | AR14: 53 | AS14: 0 | AT14: 40 | AU14: 0 | AV14: 0 | AW14: + | AX14: 31 | AY14: 15 | AZ14: 4 | BA14: 1202 | BB14: 0.125 | BC14: 0.115 | BD14: 24 | BE14: 0 | BF14: T | BG14: 0 | BH14: 0 | BI14: 1 | BJ14: 90 | BK14: 1 | BL14: 1 | BM14: 0.63 | BN14: 0
A15: 加工位置 | Q15: 石墨-钢 | R15: 插件 | S15: 15 | T15: C4 | V15: =IF(X15>0,"VDI"&W15&"-"&"Ra"&X15,"") | W15: {=INDEX(Y:Y,_xlfn.XMATCH(X15,Z:Z,0),0)} -> 0 | Y15: 13 | Z15: 0.45 | AB15: ="□"&ROUND(SQRT(3.14*(AC15/2)^2),0)&"○"&AC15 -> □50○56 | AC15: 56 | AH15: 5 | AI15: 70 | AJ15: 25 | AK15: 0 | AL15: 33 | AM15: 60 | AN15: 15 | AO15: 15 | AP15: 180 | AQ15: 03 | AR15: 73 | AS15: 0 | AT15: 40 | AU15: 0 | AV15: 0 | AW15: + | AX15: 31 | AY15: 15 | AZ15: 4 | BA15: 1202 | BB15: 0.082 | BC15: 0.0763 | BD15: 24 | BE15: 0 | BF15: T | BG15: 0 | BH15: 4 | BI15: 1 | BJ15: 90 | BK15: 1 | BL15: 1 | BM15: 0.63 | BN15: 0
A16: 加工腔数 | B16: 3 | C16: 开始高度 | D16: 4 | E16: 安全高度 | F16: 10 | Q16: 石墨-钢 | R16: 多脚 | S16: 16 | T16: C4 | V16: =IF(X16>0,"VDI"&W16&"-"&"Ra"&X16,"") | W16: {=INDEX(Y:Y,_xlfn.XMATCH(X16,Z:Z,0),0)} -> 0 | Y16: 14 | Z16: 0.5 | AB16: ="□"&ROUND(SQRT(3.14*(AC16/2)^2),0)&"○"&AC16 -> □60○68 | AC16: 68 | AH16: 4 | AI16: 40 | AJ16: 20 | AK16: 0 | AL16: 23 | AM16: 70 | AN16: 15 | AO16: 18 | AP16: 180 | AQ16: 00 | AR16: 73 | AS16: 0 | AT16: 40 | AU16: 0 | AV16: 0 | AW16: + | AX16: 31 | AY16: 15 | AZ16: 4 | BA16: 2202 | BB16: 0.052 | BC16: 0.052 | BD16: 24 | BE16: 0 | BF16: T | BG16: 0 | BH16: 2.8 | BI16: 1 | BJ16: 90 | BK16: 1 | BL16: 1 | BM16: 0.63 | BN16: 0
A17: No. | B17: 坐标系 | C17: X | D17: Y | Q17: 石墨-钢 | R17: 螺牙 | S17: 17 | T17: C4 | V17: =IF(X17>0,"VDI"&W17&"-"&"Ra"&X17,"") | W17: {=INDEX(Y:Y,_xlfn.XMATCH(X17,Z:Z,0),0)} -> 0 | Y17: 15 | Z17: 0.56 | AB17: ="□"&ROUND(SQRT(3.14*(AC17/2)^2),0)&"○"&AC17 -> □80○90 | AC17: 90 | AH17: 3 | AI17: 10 | AJ17: 9 | AK17: 0 | AL17: 15 | AM17: 80 | AN17: 15 | AO17: 18 | AP17: 180 | AQ17: 00 | AR17: 73 | AS17: 0 | AT17: 40 | AU17: 0 | AV17: 0 | AW17: + | AX17: 31 | AY17: 15 | AZ17: 5 | BA17: 2202 | BB17: 0.03 | BC17: 0.033 | BD17: 24 | BE17: 0 | BF17: T | BG17: 0 | BH17: 2 | BI17: 1 | BJ17: 90 | BK17: 1 | BL17: 1 | BM17: 0.63 | BN17: 0
A18: =IF($B$16>=M18,M18,"") -> 1 | B18: G54 | C18: 0 | D18: 0 | G18: Excel做一个按钮，一键删除所有""号，并且把名为“NC”的sheet表导出为nc文件，导出时相邻两行相同只保留一行以及删除所有空白行，要求不破坏原表格内容，同时该按钮可以复制到其他页面使用，中文输出不要乱码 | M18: 1 | N18: G054 | Q18: 石墨-钢 | R18: 蜗杆 | S18: 18 | T18: C4 | V18: =IF(X18>0,"VDI"&W18&"-"&"Ra"&X18,"") | W18: {=INDEX(Y:Y,_xlfn.XMATCH(X18,Z:Z,0),0)} -> 0 | Y18: 16 | Z18: 0.63 | AB18: ="□"&ROUND(SQRT(3.14*(AC18/2)^2),0)&"○"&AC18 -> □100○113 | AC18: 113 | AH18: 2 | AI18: 7 | AJ18: 9 | AK18: 0 | AL18: 8 | AM18: 95 | AN18: 15 | AO18: 20 | AP18: 180 | AQ18: 00 | AR18: 73 | AS18: 0 | AT18: 0 | AU18: 0 | AV18: 0 | AW18: + | AX18: 31 | AY18: 15 | AZ18: 5 | BA18: 2202 | BB18: 0.018 | BC18: 0.023 | BD18: 24 | BE18: 0 | BF18: T | BG18: 0 | BH18: 1.12 | BI18: 1 | BJ18: 90 | BK18: 1 | BL18: 1 | BM18: 0.63 | BN18: 0
A19: =IF($B$16>=M19,M19,"") -> 2 | M19: 2 | N19: G055 | Q19: 石墨-钢 | R19: 清角 | S19: 19 | T19: C4 | V19: =IF(X19>0,"VDI"&W19&"-"&"Ra"&X19,"") | W19: {=INDEX(Y:Y,_xlfn.XMATCH(X19,Z:Z,0),0)} -> 0 | Y19: 17 | Z19: 0.7 | AB19: ="□"&ROUND(SQRT(3.14*(AC19/2)^2),0)&"○"&AC19 -> □120○135 | AC19: 135 | AH19: 801 | AI19: 1 | AJ19: 9 | AK19: 0 | AL19: 15 | AM19: 110 | AN19: 15 | AO19: 20 | AP19: 180 | AQ19: 00 | AR19: 73 | AS19: 0 | AT19: 0 | AU19: 10 | AV19: 3 | AW19: - | AX19: 32 | AY19: 30 | AZ19: 5 | BA19: 3202 | BB19: -0.007 | BC19: 0.026 | BD19: 24 | BE19: 0.6 | BF19: Z | BG19: 10400 | BH19: 0.63 | BI19: 1 | BJ19: 90 | BK19: 1 | BL19: 1 | BM19: 0.63 | BN19: 0
A20: =IF($B$16>=M20,M20,"") -> 3 | M20: 3 | N20: G056 | Q20: 石墨-钢 | R20: 进胶口 | S20: 20 | T20: C4 | V20: =IF(X20>0,"VDI"&W20&"-"&"Ra"&X20,"") | W20: {=INDEX(Y:Y,_xlfn.XMATCH(X20,Z:Z,0),0)} -> 0 | Y20: 18 | Z20: 0.8 | AB20: ="□"&ROUND(SQRT(3.14*(AC20/2)^2),0)&"○"&AC20 -> □150○169 | AC20: 169 | AH20: 801 | AI20: 1 | AJ20: 9 | AK20: 0 | AL20: 15 | AM20: 110 | AN20: 15 | AO20: 20 | AP20: 180 | AQ20: 00 | AR20: 73 | AS20: 0 | AT20: 0 | AU20: 10 | AV20: 3 | AW20: - | AX20: 32 | AY20: 30 | AZ20: 5 | BA20: 3202 | BB20: 0.013 | BC20: 0.011 | BD20: 24 | BE20: 0.6 | BF20: Z | BG20: 312 | BH20: 0.63 | BI20: 1 | BJ20: 90 | BK20: 1 | BL20: 1 | BM20: 0.63 | BN20: 0
A21: =IF($B$16>=M21,M21,"") | M21: 4 | N21: G057 | Q21: 铜-钨钢 | R21: 通用 | S21: 21 | V21: =IF(X21>0,"VDI"&W21&"-"&"Ra"&X21,"") | W21: {=INDEX(Y:Y,_xlfn.XMATCH(X21,Z:Z,0),0)} -> 0 | Y21: 19 | Z21: 0.9 | AB21: ="□"&ROUND(SQRT(3.14*(AC21/2)^2),0)&"○"&AC21 -> □200○226 | AC21: 226 | AH21: 7 | AI21: 300 | AJ21: 55 | AK21: 0 | AL21: 135 | AM21: 50 | AN21: 15 | AO21: 15 | AP21: 180 | AQ21: 03 | AR21: 31 | AS21: 0 | AT21: 0 | AU21: 1 | AV21: 0 | AW21: + | AX21: 21 | AY21: 10 | AZ21: 3 | BA21: 1502 | BB21: 0.264 | BC21: 0.2323 | BD21: 24 | BE21: 0 | BF21: T | BG21: 0 | BH21: 0 | BI21: 1 | BJ21: 90 | BK21: 1 | BL21: 1 | BM21: 0.8 | BN21: 0
A22: =IF($B$16>=M22,M22,"") | M22: 5 | N22: G058 | Q22: 铜-钨钢 | R22: 深腔 | S22: 22 | V22: =IF(X22>0,"VDI"&W22&"-"&"Ra"&X22,"") | W22: {=INDEX(Y:Y,_xlfn.XMATCH(X22,Z:Z,0),0)} -> 0 | Y22: 20 | Z22: 1 | AB22: ="□"&ROUND(SQRT(3.14*(AC22/2)^2),0)&"○"&AC22 -> □0○0 | AC22: 0 | AH22: 6 | AI22: 200 | AJ22: 40 | AK22: 0 | AL22: 85 | AM22: 50 | AN22: 15 | AO22: 15 | AP22: 180 | AQ22: 03 | AR22: 32 | AS22: 0 | AT22: 0 | AU22: 1 | AV22: 0 | AW22: + | AX22: 31 | AY22: 15 | AZ22: 4 | BA22: 1502 | BB22: 0.17 | BC22: 0.1547 | BD22: 24 | BE22: 0 | BF22: T | BG22: 0 | BH22: 0 | BI22: 1 | BJ22: 90 | BK22: 1 | BL22: 1 | BM22: 0.8 | BN22: 0
A23: =IF($B$16>=M23,M23,"") | M23: 6 | N23: G059 | Q23: 铜-钨钢 | R23: 大面积 | S23: 23 | V23: =IF(X23>0,"VDI"&W23&"-"&"Ra"&X23,"") | W23: {=INDEX(Y:Y,_xlfn.XMATCH(X23,Z:Z,0),0)} -> 0 | Y23: 21 | Z23: 1.12 | AB23: ="□"&ROUND(SQRT(3.14*(AC23/2)^2),0)&"○"&AC23 -> □0○ | AH23: 5 | AI23: 140 | AJ23: 40 | AK23: 0 | AL23: 53 | AM23: 60 | AN23: 15 | AO23: 15 | AP23: 180 | AQ23: 03 | AR23: 53 | AS23: 0 | AT23: 40 | AU23: 0 | AV23: 0 | AW23: + | AX23: 31 | AY23: 15 | AZ23: 4 | BA23: 1202 | BB23: 0.115 | BC23: 0.1058 | BD23: 24 | BE23: 0 | BF23: T | BG23: 0 | BH23: 0 | BI23: 1 | BJ23: 90 | BK23: 1 | BL23: 1 | BM23: 0.8 | BN23: 0
A24: =IF($B$16>=M24,M24,"") | M24: 7 | N24: G064 | Q24: 铜-钨钢 | R24: 骨位 | S24: 24 | V24: =IF(X24>0,"VDI"&W24&"-"&"Ra"&X24,"") | W24: {=INDEX(Y:Y,_xlfn.XMATCH(X24,Z:Z,0),0)} -> 0 | Y24: 22 | Z24: 1.26 | AB24: ="□"&ROUND(SQRT(3.14*(AC24/2)^2),0)&"○"&AC24 -> □0○ | AH24: 4 | AI24: 70 | AJ24: 25 | AK24: 0 | AL24: 33 | AM24: 60 | AN24: 15 | AO24: 15 | AP24: 180 | AQ24: 03 | AR24: 73 | AS24: 0 | AT24: 40 | AU24: 0 | AV24: 0 | AW24: + | AX24: 31 | AY24: 15 | AZ24: 4 | BA24: 1202 | BB24: 0.072 | BC24: 0.067 | BD24: 24 | BE24: 0 | BF24: T | BG24: 0 | BH24: 4 | BI24: 1 | BJ24: 90 | BK24: 1 | BL24: 1 | BM24: 0.8 | BN24: 0
A25: =IF($B$16>=M25,M25,"") | M25: 8 | N25: G065 | Q25: 铜-钨钢 | R25: 插件 | S25: 25 | V25: =IF(X25>0,"VDI"&W25&"-"&"Ra"&X25,"") | W25: {=INDEX(Y:Y,_xlfn.XMATCH(X25,Z:Z,0),0)} -> 0 | Y25: 23 | Z25: 1.4 | AB25: ="□"&ROUND(SQRT(3.14*(AC25/2)^2),0)&"○"&AC25 -> □0○ | AH25: 3 | AI25: 40 | AJ25: 20 | AK25: 0 | AL25: 23 | AM25: 70 | AN25: 15 | AO25: 18 | AP25: 180 | AQ25: 00 | AR25: 73 | AS25: 0 | AT25: 40 | AU25: 0 | AV25: 0 | AW25: + | AX25: 31 | AY25: 15 | AZ25: 4 | BA25: 2202 | BB25: 0.042 | BC25: 0.042 | BD25: 24 | BE25: 0 | BF25: T | BG25: 0 | BH25: 2.8 | BI25: 1 | BJ25: 90 | BK25: 1 | BL25: 1 | BM25: 0.8 | BN25: 0
A26: =IF($B$16>=M26,M26,"") | M26: 9 | N26: G066 | Q26: 铜-钨钢 | R26: 多脚 | S26: 26 | V26: =IF(X26>0,"VDI"&W26&"-"&"Ra"&X26,"") | W26: {=INDEX(Y:Y,_xlfn.XMATCH(X26,Z:Z,0),0)} -> 0 | Y26: 24 | Z26: 1.6 | AH26: 2 | AI26: 10 | AJ26: 9 | AK26: 0 | AL26: 15 | AM26: 80 | AN26: 15 | AO26: 18 | AP26: 180 | AQ26: 00 | AR26: 73 | AS26: 0 | AT26: 40 | AU26: 0 | AV26: 0 | AW26: + | AX26: 31 | AY26: 15 | AZ26: 5 | BA26: 2202 | BB26: 0.02 | BC26: 0.022 | BD26: 24 | BE26: 0 | BF26: T | BG26: 0 | BH26: 2 | BI26: 1 | BJ26: 90 | BK26: 1 | BL26: 1 | BM26: 0.8 | BN26: 0
A27: =IF($B$16>=M27,M27,"") | M27: 10 | N27: G067 | Q27: 铜-钨钢 | R27: 螺牙 | S27: 27 | V27: =IF(X27>0,"VDI"&W27&"-"&"Ra"&X27,"") | W27: {=INDEX(Y:Y,_xlfn.XMATCH(X27,Z:Z,0),0)} -> 0 | Y27: 25 | Z27: 1.8 | AH27: 1 | AI27: 4 | AJ27: 9 | AK27: 0 | AL27: 5 | AM27: 110 | AN27: 15 | AO27: 20 | AP27: 180 | AQ27: 00 | AR27: 73 | AS27: 0 | AT27: 0 | AU27: 0 | AV27: 1 | AW27: + | AX27: 31 | AY27: 15 | AZ27: 5 | BA27: 3202 | BB27: 0.001 | BC27: 0.011 | BD27: 24 | BE27: 0 | BF27: T | BG27: 0 | BH27: 0.8 | BI27: 1 | BJ27: 90 | BK27: 1 | BL27: 1 | BM27: 0.8 | BN27: 0
A28: =IF($B$16>=M28,M28,"") | M28: 11 | N28: G068 | Q28: 铜-钨钢 | R28: 蜗杆 | S28: 28 | V28: =IF(X28>0,"VDI"&W28&"-"&"Ra"&X28,"") | W28: {=INDEX(Y:Y,_xlfn.XMATCH(X28,Z:Z,0),0)} -> 0 | Y28: 26 | Z28: 2 | AH28: 7 | AI28: 300 | AJ28: 55 | AK28: 0 | AL28: 135 | AM28: 50 | AN28: 15 | AO28: 15 | AP28: 180 | AQ28: 03 | AR28: 31 | AS28: 0 | AT28: 0 | AU28: 1 | AV28: 0 | AW28: + | AX28: 21 | AY28: 10 | AZ28: 3 | BA28: 1502 | BB28: 0.264 | BC28: 0.2323 | BD28: 24 | BE28: 0 | BF28: T | BG28: 0 | BH28: 0 | BI28: 1 | BJ28: 90 | BK28: 1 | BL28: 1 | BM28: 1.12 | BN28: 0
A29: =IF($B$16>=M29,M29,"") | M29: 12 | N29: G069 | Q29: 铜-钨钢 | R29: 清角 | S29: 29 | V29: =IF(X29>0,"VDI"&W29&"-"&"Ra"&X29,"") | W29: {=INDEX(Y:Y,_xlfn.XMATCH(X29,Z:Z,0),0)} -> 0 | Y29: 27 | Z29: 2.2 | AF29: =125*125-70*70 -> 10725 | AH29: 6 | AI29: 200 | AJ29: 40 | AK29: 0 | AL29: 85 | AM29: 50 | AN29: 15 | AO29: 15 | AP29: 180 | AQ29: 03 | AR29: 32 | AS29: 0 | AT29: 0 | AU29: 1 | AV29: 0 | AW29: + | AX29: 31 | AY29: 15 | AZ29: 4 | BA29: 1502 | BB29: 0.17 | BC29: 0.1547 | BD29: 24 | BE29: 0 | BF29: T | BG29: 0 | BH29: 0 | BI29: 1 | BJ29: 90 | BK29: 1 | BL29: 1 | BM29: 1.12 | BN29: 0
A30: =IF($B$16>=M30,M30,"") | M30: 13 | N30: G074 | Q30: 铜-钨钢 | R30: 进胶口 | S30: 30 | V30: =IF(X30>0,"VDI"&W30&"-"&"Ra"&X30,"") | W30: {=INDEX(Y:Y,_xlfn.XMATCH(X30,Z:Z,0),0)} -> 0 | Y30: 28 | Z30: 2.5 | AH30: 5 | AI30: 140 | AJ30: 40 | AK30: 0 | AL30: 53 | AM30: 60 | AN30: 15 | AO30: 15 | AP30: 180 | AQ30: 03 | AR30: 53 | AS30: 0 | AT30: 40 | AU30: 0 | AV30: 0 | AW30: + | AX30: 31 | AY30: 15 | AZ30: 4 | BA30: 1202 | BB30: 0.115 | BC30: 0.1058 | BD30: 24 | BE30: 0 | BF30: T | BG30: 0 | BH30: 0 | BI30: 1 | BJ30: 90 | BK30: 1 | BL30: 1 | BM30: 1.12 | BN30: 0
A31: =IF($B$16>=M31,M31,"") | M31: 14 | N31: G075 | Q31: 铜-铜 | R31: 通用 | S31: 31 | V31: =IF(X31>0,"VDI"&W31&"-"&"Ra"&X31,"") | W31: {=INDEX(Y:Y,_xlfn.XMATCH(X31,Z:Z,0),0)} -> 0 | Y31: 29 | Z31: 2.8 | AH31: 4 | AI31: 70 | AJ31: 25 | AK31: 0 | AL31: 33 | AM31: 60 | AN31: 15 | AO31: 15 | AP31: 180 | AQ31: 03 | AR31: 73 | AS31: 0 | AT31: 40 | AU31: 0 | AV31: 0 | AW31: + | AX31: 31 | AY31: 15 | AZ31: 4 | BA31: 1202 | BB31: 0.072 | BC31: 0.067 | BD31: 24 | BE31: 0 | BF31: T | BG31: 0 | BH31: 4 | BI31: 1 | BJ31: 90 | BK31: 1 | BL31: 1 | BM31: 1.12 | BN31: 0
A32: =IF($B$16>=M32,M32,"") | M32: 15 | N32: G076 | Q32: 铜-铜 | R32: 深腔 | S32: 32 | V32: =IF(X32>0,"VDI"&W32&"-"&"Ra"&X32,"") | W32: {=INDEX(Y:Y,_xlfn.XMATCH(X32,Z:Z,0),0)} -> 0 | Y32: 30 | Z32: 3.2 | AH32: 3 | AI32: 40 | AJ32: 20 | AK32: 0 | AL32: 23 | AM32: 70 | AN32: 15 | AO32: 18 | AP32: 180 | AQ32: 00 | AR32: 73 | AS32: 0 | AT32: 40 | AU32: 0 | AV32: 0 | AW32: + | AX32: 31 | AY32: 15 | AZ32: 4 | BA32: 2202 | BB32: 0.042 | BC32: 0.042 | BD32: 24 | BE32: 0 | BF32: T | BG32: 0 | BH32: 2.8 | BI32: 1 | BJ32: 90 | BK32: 1 | BL32: 1 | BM32: 1.12 | BN32: 0
A33: =IF($B$16>=M33,M33,"") | M33: 16 | N33: G077 | Q33: 铜-铜 | R33: 大面积 | S33: 33 | V33: =IF(X33>0,"VDI"&W33&"-"&"Ra"&X33,"") | W33: {=INDEX(Y:Y,_xlfn.XMATCH(X33,Z:Z,0),0)} -> 0 | Y33: 31 | Z33: 3.5 | AH33: 2 | AI33: 10 | AJ33: 9 | AK33: 0 | AL33: 15 | AM33: 80 | AN33: 15 | AO33: 18 | AP33: 180 | AQ33: 00 | AR33: 73 | AS33: 0 | AT33: 40 | AU33: 0 | AV33: 0 | AW33: + | AX33: 31 | AY33: 15 | AZ33: 5 | BA33: 2202 | BB33: 0.02 | BC33: 0.022 | BD33: 24 | BE33: 0 | BF33: T | BG33: 0 | BH33: 2 | BI33: 1 | BJ33: 90 | BK33: 1 | BL33: 1 | BM33: 1.12 | BN33: 0
A34: =IF($B$16>=M34,M34,"") | M34: 17 | N34: G078 | Q34: 铜-铜 | R34: 骨位 | S34: 34 | V34: =IF(X34>0,"VDI"&W34&"-"&"Ra"&X34,"") | W34: {=INDEX(Y:Y,_xlfn.XMATCH(X34,Z:Z,0),0)} -> 0 | Y34: 32 | Z34: 4 | AH34: 1 | AI34: 7 | AJ34: 9 | AK34: 0 | AL34: 8 | AM34: 110 | AN34: 15 | AO34: 20 | AP34: 180 | AQ34: 00 | AR34: 73 | AS34: 0 | AT34: 0 | AU34: 0 | AV34: 0 | AW34: + | AX34: 31 | AY34: 15 | AZ34: 5 | BA34: 3202 | BB34: 0.014 | BC34: 0.015 | BD34: 24 | BE34: 0 | BF34: T | BG34: 0 | BH34: 1.12 | BI34: 1 | BJ34: 90 | BK34: 1 | BL34: 1 | BM34: 1.12 | BN34: 0
A35: =IF($B$16>=M35,M35,"") | M35: 18 | N35: G079 | Q35: 铜-铜 | R35: 插件 | S35: 35 | V35: =IF(X35>0,"VDI"&W35&"-"&"Ra"&X35,"") | W35: {=INDEX(Y:Y,_xlfn.XMATCH(X35,Z:Z,0),0)} -> 0 | Y35: 33 | Z35: 4.5 | AH35: 6 | AI35: 300 | AJ35: 55 | AK35: 0 | AL35: 135 | AM35: 50 | AN35: 15 | AO35: 15 | AP35: 180 | AQ35: 03 | AR35: 31 | AS35: 0 | AT35: 0 | AU35: 1 | AV35: 0 | AW35: + | AX35: 21 | AY35: 10 | AZ35: 3 | BA35: 1502 | BB35: 0.261 | BC35: 0.2297 | BD35: 24 | BE35: 0 | BF35: T | BG35: 0 | BH35: 0 | BI35: 1 | BJ35: 90 | BK35: 1 | BL35: 1 | BM35: 1.6 | BN35: 0
A36: =IF($B$16>=M36,M36,"") | M36: 19 | Q36: 铜-铜 | R36: 多脚 | S36: 36 | V36: =IF(X36>0,"VDI"&W36&"-"&"Ra"&X36,"") | W36: {=INDEX(Y:Y,_xlfn.XMATCH(X36,Z:Z,0),0)} -> 0 | Y36: 34 | Z36: 5 | AH36: 5 | AI36: 200 | AJ36: 40 | AK36: 0 | AL36: 85 | AM36: 50 | AN36: 15 | AO36: 15 | AP36: 180 | AQ36: 03 | AR36: 32 | AS36: 0 | AT36: 0 | AU36: 1 | AV36: 0 | AW36: + | AX36: 31 | AY36: 15 | AZ36: 4 | BA36: 1502 | BB36: 0.167 | BC36: 0.152 | BD36: 24 | BE36: 0 | BF36: T | BG36: 0 | BH36: 0 | BI36: 1 | BJ36: 90 | BK36: 1 | BL36: 1 | BM36: 1.6 | BN36: 0
A37: =IF($B$16>=M37,M37,"") | M37: 20 | Q37: 铜-铜 | R37: 螺牙 | S37: 37 | V37: =IF(X37>0,"VDI"&W37&"-"&"Ra"&X37,"") | W37: {=INDEX(Y:Y,_xlfn.XMATCH(X37,Z:Z,0),0)} -> 0 | Y37: 35 | Z37: 5.6 | AH37: 4 | AI37: 140 | AJ37: 40 | AK37: 0 | AL37: 53 | AM37: 60 | AN37: 15 | AO37: 15 | AP37: 180 | AQ37: 03 | AR37: 53 | AS37: 0 | AT37: 40 | AU37: 0 | AV37: 0 | AW37: + | AX37: 31 | AY37: 15 | AZ37: 4 | BA37: 1202 | BB37: 0.112 | BC37: 0.103 | BD37: 24 | BE37: 0 | BF37: T | BG37: 0 | BH37: 0 | BI37: 1 | BJ37: 90 | BK37: 1 | BL37: 1 | BM37: 1.6 | BN37: 0
A38: =IF($B$16>=M38,M38,"") | M38: 21 | Q38: 铜-铜 | R38: 蜗杆 | S38: 38 | V38: =IF(X38>0,"VDI"&W38&"-"&"Ra"&X38,"") | W38: {=INDEX(Y:Y,_xlfn.XMATCH(X38,Z:Z,0),0)} -> 0 | Y38: 36 | Z38: 6.3 | AH38: 3 | AI38: 70 | AJ38: 25 | AK38: 0 | AL38: 33 | AM38: 60 | AN38: 15 | AO38: 15 | AP38: 180 | AQ38: 03 | AR38: 73 | AS38: 0 | AT38: 40 | AU38: 0 | AV38: 0 | AW38: + | AX38: 31 | AY38: 15 | AZ38: 4 | BA38: 1202 | BB38: 0.069 | BC38: 0.0642 | BD38: 24 | BE38: 0 | BF38: T | BG38: 0 | BH38: 4 | BI38: 1 | BJ38: 90 | BK38: 1 | BL38: 1 | BM38: 1.6 | BN38: 0
A39: =IF($B$16>=M39,M39,"") | M39: 22 | Q39: 铜-铜 | R39: 清角 | S39: 39 | V39: =IF(X39>0,"VDI"&W39&"-"&"Ra"&X39,"") | W39: {=INDEX(Y:Y,_xlfn.XMATCH(X39,Z:Z,0),0)} -> 0 | Y39: 37 | Z39: 7 | AH39: 2 | AI39: 40 | AJ39: 20 | AK39: 0 | AL39: 23 | AM39: 70 | AN39: 15 | AO39: 18 | AP39: 180 | AQ39: 00 | AR39: 73 | AS39: 0 | AT39: 40 | AU39: 0 | AV39: 0 | AW39: + | AX39: 31 | AY39: 15 | AZ39: 4 | BA39: 2202 | BB39: 0.039 | BC39: 0.039 | BD39: 24 | BE39: 0 | BF39: T | BG39: 0 | BH39: 2.8 | BI39: 1 | BJ39: 90 | BK39: 1 | BL39: 1 | BM39: 1.6 | BN39: 0
A40: =IF($B$16>=M40,M40,"") | M40: 23 | Q40: 铜-铜 | R40: 进胶口 | S40: 40 | V40: =IF(X40>0,"VDI"&W40&"-"&"Ra"&X40,"") | W40: {=INDEX(Y:Y,_xlfn.XMATCH(X40,Z:Z,0),0)} -> 0 | Y40: 38 | Z40: 8 | AH40: 1 | AI40: 7 | AJ40: 10 | AK40: 0 | AL40: 13 | AM40: 85 | AN40: 15 | AO40: 18 | AP40: 180 | AQ40: 00 | AR40: 73 | AS40: 0 | AT40: 40 | AU40: 0 | AV40: 0 | AW40: + | AX40: 31 | AY40: 15 | AZ40: 4 | BA40: 3202 | BB40: 0.025 | BC40: 0.023 | BD40: 24 | BE40: 0 | BF40: T | BG40: 0 | BH40: 1.6 | BI40: 1 | BJ40: 90 | BK40: 1 | BL40: 1 | BM40: 1.6 | BN40: 0
...

Sheet 逻辑层
A1: ( | B1: EX | C1: ON | D1: OFF | E1: MA | F1: IP | G1: SV | H1: UP | I1: DN | J1: LN | K1: LP | L1: STEP | M1: PL | N1: V | O1: HP | P1: PP | Q1: C | R1: S | S1: L | T1: AL | U1: JS | V1: JM | W1: OC | X1: LD) | Y1: ; | Z1: 底部余量 | AA1: 侧面余量 | AB1: 定时 | AC1: 定时时间 | AD1: 数据库说明：通过电极形状选择数据表，每个数据表内包含不同的材料，有常规参数和切入参数，切入参数用于第一行加工。
A2: {=TEXT(INDEX(BB1:BB108,_xlfn.XMATCH(EDM自动!$B$12,$BW$1:$BW$108,-1))+1,"C000")} -> C006 | B2: = | C2: {=TEXT(INDEX(INDIRECT("'"&EDM自动!$B$3&"'!c1:c9999"),_xlfn.XMATCH(EDM自动!$G$2&EDM自动!$G$3&EDM自动!$G$11&"1"&EDM自动!$B$12,INDIRECT("'"&EDM自动!$B$3&"'!AC1:AC9999")&INDIRECT("'"&EDM自动!$B$3&"'!AE1:AE9999")&INDIRECT("'"&EDM自动!$B$3&"'!AF1:AF9999")&INDIRECT("'"&EDM自动!$B$3&"'!AH1:AH9999")&INDIRECT("'"&EDM自动!$B$3&"'!W1:W9999"),-1)),"0000")} -> 0110 | D2: {=TEXT(INDEX(INDIRECT("'"&EDM自动!$B$3&"'!D1:D9999"),_xlfn.XMATCH(EDM自动!$G$2&EDM自动!$G$3&EDM自动!$G$11&"1"&EDM自动!$B$12,INDIRECT("'"&EDM自动!$B$3&"'!AC1:AC9999")&INDIRECT("'"&EDM自动!$B$3&"'!AE1:AE9999")&INDIRECT("'"&EDM自动!$B$3&"'!AF1:AF9999")&INDIRECT("'"&EDM自动!$B$3&"'!AH1:AH9999")&INDIRECT("'"&EDM自动!$B$3&"'!W1:W9999"),-1)),"0000")} -> 0030 | E2: {=TEXT(INDEX(INDIRECT("'"&EDM自动!$B$3&"'!e1:e9999"),_xlfn.XMATCH(EDM自动!$G$2&EDM自动!$G$3&EDM自动!$G$11&"1"&EDM自动!$B$12,INDIRECT("'"&EDM自动!$B$3&"'!AC1:AC9999")&INDIRECT("'"&EDM自动!$B$3&"'!AE1:AE9999")&INDIRECT("'"&EDM自动!$B$3&"'!AF1:AF9999")&INDIRECT("'"&EDM自动!$B$3&"'!AH1:AH9999")&INDIRECT("'"&EDM自动!$B$3&"'!W1:W9999"),-1)),"0000")} -> 0000 | F2: {=TEXT(INDEX(INDIRECT("'"&EDM自动!$B$3&"'!f1:f9999"),_xlfn.XMATCH(EDM自动!$G$2&EDM自动!$G$3&EDM自动!$G$11&"1"&EDM自动!$B$12,INDIRECT("'"&EDM自动!$B$3&"'!AC1:AC9999")&INDIRECT("'"&EDM自动!$B$3&"'!AE1:AE9999")&INDIRECT("'"&EDM自动!$B$3&"'!AF1:AF9999")&INDIRECT("'"&EDM自动!$B$3&"'!AH1:AH9999")&INDIRECT("'"&EDM自动!$B$3&"'!W1:W9999"),-1)),"0000")} -> 0033 | G2: {=TEXT(INDEX(INDIRECT("'"&EDM自动!$B$3&"'!g1:g9999"),_xlfn.XMATCH(EDM自动!$G$2&EDM自动!$G$3&EDM自动!$G$11&"1"&EDM自动!$B$12,INDIRECT("'"&EDM自动!$B$3&"'!AC1:AC9999")&INDIRECT("'"&EDM自动!$B$3&"'!AE1:AE9999")&INDIRECT("'"&EDM自动!$B$3&"'!AF1:AF9999")&INDIRECT("'"&EDM自动!$B$3&"'!AH1:AH9999")&INDIRECT("'"&EDM自动!$B$3&"'!W1:W9999"),-1)),"000")} -> 055 | H2: {=TEXT(INDEX(INDIRECT("'"&EDM自动!$B$3&"'!h1:h9999"),_xlfn.XMATCH(EDM自动!$G$2&EDM自动!$G$3&EDM自动!$G$11&"1"&EDM自动!$B$12,INDIRECT("'"&EDM自动!$B$3&"'!AC1:AC9999")&INDIRECT("'"&EDM自动!$B$3&"'!AE1:AE9999")&INDIRECT("'"&EDM自动!$B$3&"'!AF1:AF9999")&INDIRECT("'"&EDM自动!$B$3&"'!AH1:AH9999")&INDIRECT("'"&EDM自动!$B$3&"'!W1:W9999"),-1)),"000")} -> 011 | I2: {=TEXT(INDEX(INDIRECT("'"&EDM自动!$B$3&"'!i1:i9999"),_xlfn.XMATCH(EDM自动!$G$2&EDM自动!$G$3&EDM自动!$G$11&"1"&EDM自动!$B$12,INDIRECT("'"&EDM自动!$B$3&"'!AC1:AC9999")&INDIRECT("'"&EDM自动!$B$3&"'!AE1:AE9999")&INDIRECT("'"&EDM自动!$B$3&"'!AF1:AF9999")&INDIRECT("'"&EDM自动!$B$3&"'!AH1:AH9999")&INDIRECT("'"&EDM自动!$B$3&"'!W1:W9999"),-1)),"000")} -> 009 | J2: =TEXT(IF(AA2=0,"",0),"000") -> 000 | K2: =IF(AA2=0,"",IF(A2=0,"",EDM自动!$C$9)) -> LP=1234 | L2: =TEXT(IF(AA2=0,"",0),"0.000") -> 0.000 | M2: {=INDEX(INDIRECT("'"&EDM自动!$B$3&"'!q1:q9999"),_xlfn.XMATCH(EDM自动!$G$2&EDM自动!$G$3&EDM自动!$G$11&"1"&EDM自动!$B$12,INDIRECT("'"&EDM自动!$B$3&"'!AC1:AC9999")&INDIRECT("'"&EDM自动!$B$3&"'!AE1:AE9999")&INDIRECT("'"&EDM自动!$B$3&"'!AF1:AF9999")&INDIRECT("'"&EDM自动!$B$3&"'!AH1:AH9999")&INDIRECT("'"&EDM自动!$B$3&"'!W1:W9999"),-1))} -> + | N2: {=TEXT(LEFT(INDEX(INDIRECT("'"&EDM自动!$B$3&"'!r1:r9999"),_xlfn.XMATCH(EDM自动!$G$2&EDM自动!$G$3&EDM自动!$G$11&"1"&EDM自动!$B$12,INDIRECT("'"&EDM自动!$B$3&"'!AC1:AC9999")&INDIRECT("'"&EDM自动!$B$3&"'!AE1:AE9999")&INDIRECT("'"&EDM自动!$B$3&"'!AF1:AF9999")&INDIRECT("'"&EDM自动!$B$3&"'!AH1:AH9999")&INDIRECT("'"&EDM自动!$B$3&"'!W1:W9999"),-1)),1),"00")} -> 02 | O2: {=TEXT(INDEX(INDIRECT("'"&EDM自动!$B$3&"'!n1:n9999"),_xlfn.XMATCH(EDM自动!$G$2&EDM自动!$G$3&EDM自动!$G$11&"1"&EDM自动!$B$12,INDIRECT("'"&EDM自动!$B$3&"'!AC1:AC9999")&INDIRECT("'"&EDM自动!$B$3&"'!AE1:AE9999")&INDIRECT("'"&EDM自动!$B$3&"'!AF1:AF9999")&INDIRECT("'"&EDM自动!$B$3&"'!AH1:AH9999")&INDIRECT("'"&EDM自动!$B$3&"'!W1:W9999"),-1)),"000")} -> 000 | P2: {=TEXT(INDEX(INDIRECT("'"&EDM自动!$B$3&"'!o1:o9999"),_xlfn.XMATCH(EDM自动!$G$2&EDM自动!$G$3&EDM自动!$G$11&"1"&EDM自动!$B$12,INDIRECT("'"&EDM自动!$B$3&"'!AC1:AC9999")&INDIRECT("'"&EDM自动!$B$3&"'!AE1:AE9999")&INDIRECT("'"&EDM自动!$B$3&"'!AF1:AF9999")&INDIRECT("'"&EDM自动!$B$3&"'!AH1:AH9999")&INDIRECT("'"&EDM自动!$B$3&"'!W1:W9999"),-1)),"00")} -> 11 | Q2: {=INDEX(INDIRECT("'"&EDM自动!$B$3&"'!p1:p9999"),_xlfn.XMATCH(EDM自动!$G$2&EDM自动!$G$3&EDM自动!$G$11&"1"&EDM自动!$B$12,INDIRECT("'"&EDM自动!$B$3&"'!AC1:AC9999")&INDIRECT("'"&EDM自动!$B$3&"'!AE1:AE9999")&INDIRECT("'"&EDM自动!$B$3&"'!AF1:AF9999")&INDIRECT("'"&EDM自动!$B$3&"'!AH1:AH9999")&INDIRECT("'"&EDM自动!$B$3&"'!W1:W9999"),-1))} -> 0 | R2: {=INDEX(INDIRECT("'"&EDM自动!$B$3&"'!l1:l9999"),_xlfn.XMATCH(EDM自动!$G$2&EDM自动!$G$3&EDM自动!$G$11&"1"&EDM自动!$B$12,INDIRECT("'"&EDM自动!$B$3&"'!AC1:AC9999")&INDIRECT("'"&EDM自动!$B$3&"'!AE1:AE9999")&INDIRECT("'"&EDM自动!$B$3&"'!AF1:AF9999")&INDIRECT("'"&EDM自动!$B$3&"'!AH1:AH9999")&INDIRECT("'"&EDM自动!$B$3&"'!W1:W9999"),-1))} -> 22 | S2: {=TEXT(INDEX(INDIRECT("'"&EDM自动!$B$3&"'!t1:t9999"),_xlfn.XMATCH(EDM自动!$G$2&EDM自动!$G$3&EDM自动!$G$11&EDM自动!$G$6&"1"&EDM自动!$B$12,INDIRECT("'"&EDM自动!$B$3&"'!AC1:AC9999")&INDIRECT("'"&EDM自动!$B$3&"'!AE1:AE9999")&INDIRECT("'"&EDM自动!$B$3&"'!AF1:AF9999")&INDIRECT("'"&EDM自动!$B$3&"'!AH1:AH9999")&INDIRECT("'"&EDM自动!$B$3&"'!W1:W9999"),-1)),"00")} -> 02 | T2: {=TEXT(INDEX(INDIRECT("'"&EDM自动!$B$3&"'!s1:s9999"),_xlfn.XMATCH(EDM自动!$G$2&EDM自动!$G$3&EDM自动!$G$11&"1"&EDM自动!$B$12,INDIRECT("'"&EDM自动!$B$3&"'!AC1:AC9999")&INDIRECT("'"&EDM自动!$B$3&"'!AE1:AE9999")&INDIRECT("'"&EDM自动!$B$3&"'!AF1:AF9999")&INDIRECT("'"&EDM自动!$B$3&"'!AH1:AH9999")&INDIRECT("'"&EDM自动!$B$3&"'!W1:W9999"),-1)),"00")} -> 10 | U2: {=TEXT(INDEX(INDIRECT("'"&EDM自动!$B$3&"'!j1:j9999"),_xlfn.XMATCH(EDM自动!$G$2&EDM自动!$G$3&EDM自动!$G$11&"1"&EDM自动!$B$12,INDIRECT("'"&EDM自动!$B$3&"'!AC1:AC9999")&INDIRECT("'"&EDM自动!$B$3&"'!AE1:AE9999")&INDIRECT("'"&EDM自动!$B$3&"'!AF1:AF9999")&INDIRECT("'"&EDM自动!$B$3&"'!AH1:AH9999")&INDIRECT("'"&EDM自动!$B$3&"'!W1:W9999"),-1)),"000")} -> 075 | V2: {=TEXT(INDEX(INDIRECT("'"&EDM自动!$B$3&"'!k1:k9999"),_xlfn.XMATCH(EDM自动!$G$2&EDM自动!$G$3&EDM自动!$G$11&"1"&EDM自动!$B$12,INDIRECT("'"&EDM自动!$B$3&"'!AC1:AC9999")&INDIRECT("'"&EDM自动!$B$3&"'!AE1:AE9999")&INDIRECT("'"&EDM自动!$B$3&"'!AF1:AF9999")&INDIRECT("'"&EDM自动!$B$3&"'!AH1:AH9999")&INDIRECT("'"&EDM自动!$B$3&"'!W1:W9999"),-1)),"00")} -> 03 | W2: {=TEXT(INDEX(INDIRECT("'"&EDM自动!$B$3&"'!m1:m9999"),_xlfn.XMATCH(EDM自动!$G$2&EDM自动!$G$3&EDM自动!$G$11&"1"&EDM自动!$B$12,INDIRECT("'"&EDM自动!$B$3&"'!AC1:AC9999")&INDIRECT("'"&EDM自动!$B$3&"'!AE1:AE9999")&INDIRECT("'"&EDM自动!$B$3&"'!AF1:AF9999")&INDIRECT("'"&EDM自动!$B$3&"'!AH1:AH9999")&INDIRECT("'"&EDM自动!$B$3&"'!W1:W9999"),-1)),"0000")} -> 0000 | X2: {=TEXT(INDEX(INDIRECT("'"&EDM自动!$B$3&"'!u1:u9999"),_xlfn.XMATCH(EDM自动!$G$2&EDM自动!$G$3&EDM自动!$G$11&"1"&EDM自动!$B$12,INDIRECT("'"&EDM自动!$B$3&"'!AC1:AC9999")&INDIRECT("'"&EDM自动!$B$3&"'!AE1:AE9999")&INDIRECT("'"&EDM自动!$B$3&"'!AF1:AF9999")&INDIRECT("'"&EDM自动!$B$3&"'!AH1:AH9999")&INDIRECT("'"&EDM自动!$B$3&"'!W1:W9999"),-1)),"0000")} -> 0002 | Y2: =IF(AA2=0,"",";") -> ; | Z2: {=INDEX(INDIRECT("'"&EDM自动!$B$3&"'!V1:V9999"),_xlfn.XMATCH(EDM自动!$G$2&EDM自动!$G$3&EDM自动!$G$11&"1"&EDM自动!$B$12,INDIRECT("'"&EDM自动!$B$3&"'!AC1:AC9999")&INDIRECT("'"&EDM自动!$B$3&"'!AE1:AE9999")&INDIRECT("'"&EDM自动!$B$3&"'!AF1:AF9999")&INDIRECT("'"&EDM自动!$B$3&"'!AH1:AH9999")&INDIRECT("'"&EDM自动!$B$3&"'!W1:W9999"),-1))} -> 0.137 | AA2: {=INDEX(INDIRECT("'"&EDM自动!$B$3&"'!w1:w9999"),_xlfn.XMATCH(EDM自动!$G$2&EDM自动!$G$3&EDM自动!$G$11&"1"&EDM自动!$B$12,INDIRECT("'"&EDM自动!$B$3&"'!AC1:AC9999")&INDIRECT("'"&EDM自动!$B$3&"'!AE1:AE9999")&INDIRECT("'"&EDM自动!$B$3&"'!AF1:AF9999")&INDIRECT("'"&EDM自动!$B$3&"'!AH1:AH9999")&INDIRECT("'"&EDM自动!$B$3&"'!W1:W9999"),-1))} -> 0.1 | AD2: 第一行逻辑：通过【EDM自动】中的材料、形状、重视以及写死的切入为“1”筛选出参数组，再根据【EDM自动】中设定单边火花位从参数组中的侧面余量一列调取一行参数
J3: =TEXT(IF(AA3=0,"",0),"000") | K3: =IF(AA3=0,"",IF(A3=0,"",EDM自动!$C$9)) | L3: =TEXT(IF(AA3=0,"",0),"0.000") | BB3: Cxx | BC3: ON | BD3: OFF | BE3: MA | BF3: IP | BG3: SV | BH3: UP | BI3: DN | BJ3: JS | BK3: JM | BL3: S | BM3: OC | BN3: HP | BO3: PP | BP3: C | BQ3: PL | BR3: V | BS3: AL | BT3: L | BU3: LD | BV3: 底部余量 | BW3: 侧面余量 | BX3: AJC | BY3: 加工速度 | BZ3: 定时 | CA3: 定时时间 | CB3: 粗糙度 | CC3: 材料 | CD3: 面积 | CE3: 形状 | CF3: 重视 | CG3: Ra | CH3: 切入
A4: {=IF(AA4=0,"",TEXT(INDEX(BB1:BB108,_xlfn.XMATCH(EDM自动!$B$12,$BW$1:$BW$108,-1)),"C000"))} -> C005 | B4: =IF(AA4=0,"","=") -> = | C4: {=TEXT(IF(AA4=0,"",INDEX(BC1:BC108,_xlfn.XMATCH(EDM自动!$B$12,$BW$1:$BW$108,-1))),"0000")} -> 0070 | D4: {=TEXT(IF(AA4=0,"",INDEX(BD1:BD108,_xlfn.XMATCH(EDM自动!$B$12,$BW$1:$BW$108,-1))),"0000")} -> 0025 | E4: {=TEXT(IF(AA4=0,"",INDEX(BE1:BE108,_xlfn.XMATCH(EDM自动!$B$12,$BW$1:$BW$108,-1))),"0000")} -> 0000 | F4: {=TEXT(IF(AA4=0,"",INDEX(BF1:BF108,_xlfn.XMATCH(EDM自动!$B$12,$BW$1:$BW$108,-1))),"0000")} -> 0033 | G4: {=TEXT(IF(AA4=0,"",INDEX(BG1:BG108,_xlfn.XMATCH(EDM自动!$B$12,$BW$1:$BW$108,-1))),"000")} -> 060 | H4: {=TEXT(IF(AA4=0,"",INDEX(BH1:BH108,_xlfn.XMATCH(EDM自动!$B$12,$BW$1:$BW$108,-1))),"000")} -> 015 | I4: {=TEXT(IF(AA4=0,"",INDEX(BI1:BI108,_xlfn.XMATCH(EDM自动!$B$12,$BW$1:$BW$108,-1))),"000")} -> 015 | J4: =TEXT(IF(AA4=0,"",0),"000") -> 000 | K4: =IF(AA4=0,"",IF(A4=0,"",EDM自动!$C$9)) -> LP=1234 | L4: =TEXT(IF(AA4=0,"",0),"0.000") -> 0.000 | M4: {=IF(AA4=0,"",INDEX(BQ1:BQ108,_xlfn.XMATCH(EDM自动!$B$12,$BW$1:$BW$108,-1)))} -> + | N4: {=IF(AA4=0,"",TEXT(LEFT(INDEX(BR1:BR108,_xlfn.XMATCH(EDM自动!$B$12,$BW$1:$BW$108,-1)),1),"00"))} -> 03 | O4: {=TEXT(IF(AA4=0,"",INDEX(BN1:BN108,_xlfn.XMATCH(EDM自动!$B$12,$BW$1:$BW$108,-1))),"000")} -> 040 | P4: {=TEXT(IF(AA4=0,"",INDEX(BO1:BO108,_xlfn.XMATCH(EDM自动!$B$12,$BW$1:$BW$108,-1))),"00")} -> 00 | Q4: {=IF(AA4=0,"",INDEX(BP1:BP108,_xlfn.XMATCH(EDM自动!$B$12,$BW$1:$BW$108,-1)))} -> 0 | R4: {=IF(AA4=0,"",INDEX(BL1:BL108,_xlfn.XMATCH(EDM自动!$B$12,$BW$1:$BW$108,-1)))} -> 73 | S4: {=TEXT(IF(AA4=0,"",INDEX(BT1:BT108,_xlfn.XMATCH(EDM自动!$B$12,$BW$1:$BW$108,-1))),"00")} -> 04 | T4: {=TEXT(IF(AA4=0,"",INDEX(BS1:BS108,_xlfn.XMATCH(EDM自动!$B$12,$BW$1:$BW$108,-1))),"00")} -> 15 | U4: {=TEXT(IF(AA4=0,"",INDEX(BJ1:BJ108,_xlfn.XMATCH(EDM自动!$B$12,$BW$1:$BW$108,-1))),"000")} -> 180 | V4: {=TEXT(IF(AA4=0,"",INDEX(BK1:BK108,_xlfn.XMATCH(EDM自动!$B$12,$BW$1:$BW$108,-1))),"00")} -> 03 | W4: {=TEXT(IF(AA4=0,"",INDEX(BM1:BM108,_xlfn.XMATCH(EDM自动!$B$12,$BW$1:$BW$108,-1))),"0000")} -> 0000 | X4: {=TEXT(IF(AA4=0,"",INDEX(BU1:BU108,_xlfn.XMATCH(EDM自动!$B$12,$BW$1:$BW$108,-1))),"0000")} -> 1202 | Y4: =IF(AA4=0,"",";") -> ; | Z4: {=INDEX(BV1:BV108,_xlfn.XMATCH(EDM自动!$B$12,$BW$1:$BW$108,-1))} -> 0.082 | AA4: {=INDEX(BW1:BW108,_xlfn.XMATCH(EDM自动!$B$12,$BW$1:$BW$108,-1))} -> 0.0763 | AB4: {=INDEX(BZ1:BZ108,_xlfn.XMATCH(EDM自动!$B$12,$BW$1:$BW$108,-1))} -> T | AC4: {=INDEX(CA1:CA108,_xlfn.XMATCH(EDM自动!$B$12,$BW$1:$BW$108,-1))} -> 0 | AD4: 其他逻辑：根据【EDM自动】中材料、面积、形状、重视、Ra、切入=0筛选出满足条件的整组参数，载入到右侧；再根据【EDM自动】设定单边火花位，从右侧参数的侧面余量一列向下调取参数到左侧。其中LN、LP从【EDM自动】调取，STEP设0，LN摇动模式，LP摇动形状 | BB4: {=_xlfn._xlws.FILTER(INDIRECT("'"&EDM自动!$B$3&"'!B:AH"),(INDIRECT("'"&EDM自动!$B$3&"'!AH:AH")=0)*(INDIRECT("'"&EDM自动!$B$3&"'!AC:AC")=EDM自动!$G$2)*(INDIRECT("'"&EDM自动!$B$3&"'!AE:AE")=EDM自动!$G$3)*(INDIRECT("'"&EDM自动!$B$3&"'!AF:AF")=EDM自动!$G$11)*(INDIRECT("'"&EDM自动!$B$3&"'!AG:AG")=EDM自动!$G$8)*(INDIRECT("'"&EDM自动!$B$3&"'!AD:AD")=EDM自动!$G$6))} -> 8 | BC4: 300 | BD4: 55 | BE4: 0 | BF4: 135 | BG4: 50 | BH4: 15 | BI4: 15 | BJ4: 180 | BK4: 03 | BL4: 31 | BM4: 0 | BN4: 0 | BO4: 1 | BP4: 0 | BQ4: + | BR4: 21 | BS4: 10 | BT4: 3 | BU4: 1502 | BV4: 0.274 | BW4: 0.2411 | BX4: 24 | BY4: 0 | BZ4: T | CA4: 0 | CB4: 0 | CC4: 1 | CD4: 90 | CE4: 1 | CF4: 1 | CG4: 0.63 | CH4: 0
A5: {=IF(AA5=0,"",TEXT(INDEX(BB2:BB109,_xlfn.XMATCH(EDM自动!$B$12,$BW$1:$BW$108,-1)),"C000"))} -> C004 | B5: =IF(AA5=0,"","=") -> = | C5: {=TEXT(IF(AA5=0,"",INDEX(BC2:BC109,_xlfn.XMATCH(EDM自动!$B$12,$BW$1:$BW$108,-1))),"0000")} -> 0040 | D5: {=TEXT(IF(AA5=0,"",INDEX(BD2:BD109,_xlfn.XMATCH(EDM自动!$B$12,$BW$1:$BW$108,-1))),"0000")} -> 0020 | E5: {=TEXT(IF(AA5=0,"",INDEX(BE2:BE109,_xlfn.XMATCH(EDM自动!$B$12,$BW$1:$BW$108,-1))),"0000")} -> 0000 | F5: {=TEXT(IF(AA5=0,"",INDEX(BF2:BF109,_xlfn.XMATCH(EDM自动!$B$12,$BW$1:$BW$108,-1))),"0000")} -> 0023 | G5: {=TEXT(IF(AA5=0,"",INDEX(BG2:BG109,_xlfn.XMATCH(EDM自动!$B$12,$BW$1:$BW$108,-1))),"000")} -> 070 | H5: {=TEXT(IF(AA5=0,"",INDEX(BH2:BH109,_xlfn.XMATCH(EDM自动!$B$12,$BW$1:$BW$108,-1))),"000")} -> 015 | I5: {=TEXT(IF(AA5=0,"",INDEX(BI2:BI109,_xlfn.XMATCH(EDM自动!$B$12,$BW$1:$BW$108,-1))),"000")} -> 018 | J5: =TEXT(IF(AA5=0,"",0),"000") -> 000 | K5: =IF(AA5=0,"",IF(A5=0,"",EDM自动!$C$9)) -> LP=1234 | L5: =TEXT(IF(AA5=0,"",0),"0.000") -> 0.000 | M5: {=IF(AA5=0,"",INDEX(BQ2:BQ109,_xlfn.XMATCH(EDM自动!$B$12,$BW$1:$BW$108,-1)))} -> + | N5: {=IF(AA5=0,"",TEXT(LEFT(INDEX(BR2:BR109,_xlfn.XMATCH(EDM自动!$B$12,$BW$1:$BW$108,-1)),1),"00"))} -> 03 | O5: {=TEXT(IF(AA5=0,"",INDEX(BN2:BN109,_xlfn.XMATCH(EDM自动!$B$12,$BW$1:$BW$108,-1))),"000")} -> 040 | P5: {=TEXT(IF(AA5=0,"",INDEX(BO2:BO109,_xlfn.XMATCH(EDM自动!$B$12,$BW$1:$BW$108,-1))),"00")} -> 00 | Q5: {=IF(AA5=0,"",INDEX(BP2:BP109,_xlfn.XMATCH(EDM自动!$B$12,$BW$1:$BW$108,-1)))} -> 0 | R5: {=IF(AA5=0,"",INDEX(BL2:BL109,_xlfn.XMATCH(EDM自动!$B$12,$BW$1:$BW$108,-1)))} -> 73 | S5: {=TEXT(IF(AA5=0,"",INDEX(BT2:BT109,_xlfn.XMATCH(EDM自动!$B$12,$BW$1:$BW$108,-1))),"00")} -> 04 | T5: {=TEXT(IF(AA5=0,"",INDEX(BS2:BS109,_xlfn.XMATCH(EDM自动!$B$12,$BW$1:$BW$108,-1))),"00")} -> 15 | U5: {=TEXT(IF(AA5=0,"",INDEX(BJ2:BJ109,_xlfn.XMATCH(EDM自动!$B$12,$BW$1:$BW$108,-1))),"000")} -> 180 | V5: {=TEXT(IF(AA5=0,"",INDEX(BK2:BK109,_xlfn.XMATCH(EDM自动!$B$12,$BW$1:$BW$108,-1))),"00")} -> 00 | W5: {=TEXT(IF(AA5=0,"",INDEX(BM2:BM109,_xlfn.XMATCH(EDM自动!$B$12,$BW$1:$BW$108,-1))),"0000")} -> 0000 | X5: {=TEXT(IF(AA5=0,"",INDEX(BU2:BU109,_xlfn.XMATCH(EDM自动!$B$12,$BW$1:$BW$108,-1))),"0000")} -> 2202 | Y5: =IF(AA5=0,"",";") -> ; | Z5: {=INDEX(BV2:BV109,_xlfn.XMATCH(EDM自动!$B$12,$BW$1:$BW$108,-1))} -> 0.052 | AA5: {=INDEX(BW2:BW109,_xlfn.XMATCH(EDM自动!$B$12,$BW$1:$BW$108,-1))} -> 0.052 | AB5: {=INDEX(BZ2:BZ109,_xlfn.XMATCH(EDM自动!$B$12,$BW$1:$BW$108,-1))} -> T | AC5: {=INDEX(CA2:CA109,_xlfn.XMATCH(EDM自动!$B$12,$BW$1:$BW$108,-1))} -> 0 | AD5: 把左侧有效参数整理到NC表，再做一个宏按钮一键导出 | BB5: 7 | BC5: 200 | BD5: 40 | BE5: 0 | BF5: 85 | BG5: 50 | BH5: 15 | BI5: 15 | BJ5: 180 | BK5: 03 | BL5: 32 | BM5: 0 | BN5: 0 | BO5: 1 | BP5: 0 | BQ5: + | BR5: 31 | BS5: 15 | BT5: 4 | BU5: 1502 | BV5: 0.18 | BW5: 0.1638 | BX5: 24 | BY5: 0 | BZ5: T | CA5: 0 | CB5: 0 | CC5: 1 | CD5: 90 | CE5: 1 | CF5: 1 | CG5: 0.63 | CH5: 0
A6: {=IF(AA6=0,"",TEXT(INDEX(BB3:BB110,_xlfn.XMATCH(EDM自动!$B$12,$BW$1:$BW$108,-1)),"C000"))} -> C003 | B6: =IF(AA6=0,"","=") -> = | C6: {=TEXT(IF(AA6=0,"",INDEX(BC3:BC110,_xlfn.XMATCH(EDM自动!$B$12,$BW$1:$BW$108,-1))),"0000")} -> 0010 | D6: {=TEXT(IF(AA6=0,"",INDEX(BD3:BD110,_xlfn.XMATCH(EDM自动!$B$12,$BW$1:$BW$108,-1))),"0000")} -> 0009 | E6: {=TEXT(IF(AA6=0,"",INDEX(BE3:BE110,_xlfn.XMATCH(EDM自动!$B$12,$BW$1:$BW$108,-1))),"0000")} -> 0000 | F6: {=TEXT(IF(AA6=0,"",INDEX(BF3:BF110,_xlfn.XMATCH(EDM自动!$B$12,$BW$1:$BW$108,-1))),"0000")} -> 0015 | G6: {=TEXT(IF(AA6=0,"",INDEX(BG3:BG110,_xlfn.XMATCH(EDM自动!$B$12,$BW$1:$BW$108,-1))),"000")} -> 080 | H6: {=TEXT(IF(AA6=0,"",INDEX(BH3:BH110,_xlfn.XMATCH(EDM自动!$B$12,$BW$1:$BW$108,-1))),"000")} -> 015 | I6: {=TEXT(IF(AA6=0,"",INDEX(BI3:BI110,_xlfn.XMATCH(EDM自动!$B$12,$BW$1:$BW$108,-1))),"000")} -> 018 | J6: =TEXT(IF(AA6=0,"",0),"000") -> 000 | K6: =IF(AA6=0,"",IF(A6=0,"",EDM自动!$C$9)) -> LP=1234 | L6: =TEXT(IF(AA6=0,"",0),"0.000") -> 0.000 | M6: {=IF(AA6=0,"",INDEX(BQ3:BQ110,_xlfn.XMATCH(EDM自动!$B$12,$BW$1:$BW$108,-1)))} -> + | N6: {=IF(AA6=0,"",TEXT(LEFT(INDEX(BR3:BR110,_xlfn.XMATCH(EDM自动!$B$12,$BW$1:$BW$108,-1)),1),"00"))} -> 03 | O6: {=TEXT(IF(AA6=0,"",INDEX(BN3:BN110,_xlfn.XMATCH(EDM自动!$B$12,$BW$1:$BW$108,-1))),"000")} -> 040 | P6: {=TEXT(IF(AA6=0,"",INDEX(BO3:BO110,_xlfn.XMATCH(EDM自动!$B$12,$BW$1:$BW$108,-1))),"00")} -> 00 | Q6: {=IF(AA6=0,"",INDEX(BP3:BP110,_xlfn.XMATCH(EDM自动!$B$12,$BW$1:$BW$108,-1)))} -> 0 | R6: {=IF(AA6=0,"",INDEX(BL3:BL110,_xlfn.XMATCH(EDM自动!$B$12,$BW$1:$BW$108,-1)))} -> 73 | S6: {=TEXT(IF(AA6=0,"",INDEX(BT3:BT110,_xlfn.XMATCH(EDM自动!$B$12,$BW$1:$BW$108,-1))),"00")} -> 05 | T6: {=TEXT(IF(AA6=0,"",INDEX(BS3:BS110,_xlfn.XMATCH(EDM自动!$B$12,$BW$1:$BW$108,-1))),"00")} -> 15 | U6: {=TEXT(IF(AA6=0,"",INDEX(BJ3:BJ110,_xlfn.XMATCH(EDM自动!$B$12,$BW$1:$BW$108,-1))),"000")} -> 180 | V6: {=TEXT(IF(AA6=0,"",INDEX(BK3:BK110,_xlfn.XMATCH(EDM自动!$B$12,$BW$1:$BW$108,-1))),"00")} -> 00 | W6: {=TEXT(IF(AA6=0,"",INDEX(BM3:BM110,_xlfn.XMATCH(EDM自动!$B$12,$BW$1:$BW$108,-1))),"0000")} -> 0000 | X6: {=TEXT(IF(AA6=0,"",INDEX(BU3:BU110,_xlfn.XMATCH(EDM自动!$B$12,$BW$1:$BW$108,-1))),"0000")} -> 2202 | Y6: =IF(AA6=0,"",";") -> ; | Z6: {=INDEX(BV3:BV110,_xlfn.XMATCH(EDM自动!$B$12,$BW$1:$BW$108,-1))} -> 0.03 | AA6: {=INDEX(BW3:BW110,_xlfn.XMATCH(EDM自动!$B$12,$BW$1:$BW$108,-1))} -> 0.033 | AB6: {=INDEX(BZ3:BZ110,_xlfn.XMATCH(EDM自动!$B$12,$BW$1:$BW$108,-1))} -> T | AC6: {=INDEX(CA3:CA110,_xlfn.XMATCH(EDM自动!$B$12,$BW$1:$BW$108,-1))} -> 0 | BB6: 6 | BC6: 140 | BD6: 40 | BE6: 0 | BF6: 53 | BG6: 60 | BH6: 15 | BI6: 15 | BJ6: 180 | BK6: 03 | BL6: 53 | BM6: 0 | BN6: 40 | BO6: 0 | BP6: 0 | BQ6: + | BR6: 31 | BS6: 15 | BT6: 4 | BU6: 1202 | BV6: 0.125 | BW6: 0.115 | BX6: 24 | BY6: 0 | BZ6: T | CA6: 0 | CB6: 0 | CC6: 1 | CD6: 90 | CE6: 1 | CF6: 1 | CG6: 0.63 | CH6: 0
A7: {=IF(AA7=0,"",TEXT(INDEX(BB4:BB111,_xlfn.XMATCH(EDM自动!$B$12,$BW$1:$BW$108,-1)),"C000"))} -> C002 | B7: =IF(AA7=0,"","=") -> = | C7: {=TEXT(IF(AA7=0,"",INDEX(BC4:BC111,_xlfn.XMATCH(EDM自动!$B$12,$BW$1:$BW$108,-1))),"0000")} -> 0007 | D7: {=TEXT(IF(AA7=0,"",INDEX(BD4:BD111,_xlfn.XMATCH(EDM自动!$B$12,$BW$1:$BW$108,-1))),"0000")} -> 0009 | E7: {=TEXT(IF(AA7=0,"",INDEX(BE4:BE111,_xlfn.XMATCH(EDM自动!$B$12,$BW$1:$BW$108,-1))),"0000")} -> 0000 | F7: {=TEXT(IF(AA7=0,"",INDEX(BF4:BF111,_xlfn.XMATCH(EDM自动!$B$12,$BW$1:$BW$108,-1))),"0000")} -> 0008 | G7: {=TEXT(IF(AA7=0,"",INDEX(BG4:BG111,_xlfn.XMATCH(EDM自动!$B$12,$BW$1:$BW$108,-1))),"000")} -> 095 | H7: {=TEXT(IF(AA7=0,"",INDEX(BH4:BH111,_xlfn.XMATCH(EDM自动!$B$12,$BW$1:$BW$108,-1))),"000")} -> 015 | I7: {=TEXT(IF(AA7=0,"",INDEX(BI4:BI111,_xlfn.XMATCH(EDM自动!$B$12,$BW$1:$BW$108,-1))),"000")} -> 020 | J7: =TEXT(IF(AA7=0,"",0),"000") -> 000 | K7: =IF(AA7=0,"",IF(A7=0,"",EDM自动!$C$9)) -> LP=1234 | L7: =TEXT(IF(AA7=0,"",0),"0.000") -> 0.000 | M7: {=IF(AA7=0,"",INDEX(BQ4:BQ111,_xlfn.XMATCH(EDM自动!$B$12,$BW$1:$BW$108,-1)))} -> + | N7: {=IF(AA7=0,"",TEXT(LEFT(INDEX(BR4:BR111,_xlfn.XMATCH(EDM自动!$B$12,$BW$1:$BW$108,-1)),1),"00"))} -> 03 | O7: {=TEXT(IF(AA7=0,"",INDEX(BN4:BN111,_xlfn.XMATCH(EDM自动!$B$12,$BW$1:$BW$108,-1))),"000")} -> 000 | P7: {=TEXT(IF(AA7=0,"",INDEX(BO4:BO111,_xlfn.XMATCH(EDM自动!$B$12,$BW$1:$BW$108,-1))),"00")} -> 00 | Q7: {=IF(AA7=0,"",INDEX(BP4:BP111,_xlfn.XMATCH(EDM自动!$B$12,$BW$1:$BW$108,-1)))} -> 0 | R7: {=IF(AA7=0,"",INDEX(BL4:BL111,_xlfn.XMATCH(EDM自动!$B$12,$BW$1:$BW$108,-1)))} -> 73 | S7: {=TEXT(IF(AA7=0,"",INDEX(BT4:BT111,_xlfn.XMATCH(EDM自动!$B$12,$BW$1:$BW$108,-1))),"00")} -> 05 | T7: {=TEXT(IF(AA7=0,"",INDEX(BS4:BS111,_xlfn.XMATCH(EDM自动!$B$12,$BW$1:$BW$108,-1))),"00")} -> 15 | U7: {=TEXT(IF(AA7=0,"",INDEX(BJ4:BJ111,_xlfn.XMATCH(EDM自动!$B$12,$BW$1:$BW$108,-1))),"000")} -> 180 | V7: {=TEXT(IF(AA7=0,"",INDEX(BK4:BK111,_xlfn.XMATCH(EDM自动!$B$12,$BW$1:$BW$108,-1))),"00")} -> 00 | W7: {=TEXT(IF(AA7=0,"",INDEX(BM4:BM111,_xlfn.XMATCH(EDM自动!$B$12,$BW$1:$BW$108,-1))),"0000")} -> 0000 | X7: {=TEXT(IF(AA7=0,"",INDEX(BU4:BU111,_xlfn.XMATCH(EDM自动!$B$12,$BW$1:$BW$108,-1))),"0000")} -> 2202 | Y7: =IF(AA7=0,"",";") -> ; | Z7: {=INDEX(BV4:BV111,_xlfn.XMATCH(EDM自动!$B$12,$BW$1:$BW$108,-1))} -> 0.018 | AA7: {=INDEX(BW4:BW111,_xlfn.XMATCH(EDM自动!$B$12,$BW$1:$BW$108,-1))} -> 0.023 | AB7: {=INDEX(BZ4:BZ111,_xlfn.XMATCH(EDM自动!$B$12,$BW$1:$BW$108,-1))} -> T | AC7: {=INDEX(CA4:CA111,_xlfn.XMATCH(EDM自动!$B$12,$BW$1:$BW$108,-1))} -> 0 | BB7: 5 | BC7: 70 | BD7: 25 | BE7: 0 | BF7: 33 | BG7: 60 | BH7: 15 | BI7: 15 | BJ7: 180 | BK7: 03 | BL7: 73 | BM7: 0 | BN7: 40 | BO7: 0 | BP7: 0 | BQ7: + | BR7: 31 | BS7: 15 | BT7: 4 | BU7: 1202 | BV7: 0.082 | BW7: 0.0763 | BX7: 24 | BY7: 0 | BZ7: T | CA7: 0 | CB7: 4 | CC7: 1 | CD7: 90 | CE7: 1 | CF7: 1 | CG7: 0.63 | CH7: 0
A8: {=IF(AA8=0,"",TEXT(INDEX(BB5:BB112,_xlfn.XMATCH(EDM自动!$B$12,$BW$1:$BW$108,-1)),"C000"))} -> C801 | B8: =IF(AA8=0,"","=") -> = | C8: {=TEXT(IF(AA8=0,"",INDEX(BC5:BC112,_xlfn.XMATCH(EDM自动!$B$12,$BW$1:$BW$108,-1))),"0000")} -> 0001 | D8: {=TEXT(IF(AA8=0,"",INDEX(BD5:BD112,_xlfn.XMATCH(EDM自动!$B$12,$BW$1:$BW$108,-1))),"0000")} -> 0009 | E8: {=TEXT(IF(AA8=0,"",INDEX(BE5:BE112,_xlfn.XMATCH(EDM自动!$B$12,$BW$1:$BW$108,-1))),"0000")} -> 0000 | F8: {=TEXT(IF(AA8=0,"",INDEX(BF5:BF112,_xlfn.XMATCH(EDM自动!$B$12,$BW$1:$BW$108,-1))),"0000")} -> 0015 | G8: {=TEXT(IF(AA8=0,"",INDEX(BG5:BG112,_xlfn.XMATCH(EDM自动!$B$12,$BW$1:$BW$108,-1))),"000")} -> 110 | H8: {=TEXT(IF(AA8=0,"",INDEX(BH5:BH112,_xlfn.XMATCH(EDM自动!$B$12,$BW$1:$BW$108,-1))),"000")} -> 015 | I8: {=TEXT(IF(AA8=0,"",INDEX(BI5:BI112,_xlfn.XMATCH(EDM自动!$B$12,$BW$1:$BW$108,-1))),"000")} -> 020 | J8: =TEXT(IF(AA8=0,"",0),"000") -> 000 | K8: =IF(AA8=0,"",IF(A8=0,"",EDM自动!$C$9)) -> LP=1234 | L8: =TEXT(IF(AA8=0,"",0),"0.000") -> 0.000 | M8: {=IF(AA8=0,"",INDEX(BQ5:BQ112,_xlfn.XMATCH(EDM自动!$B$12,$BW$1:$BW$108,-1)))} -> - | N8: {=IF(AA8=0,"",TEXT(LEFT(INDEX(BR5:BR112,_xlfn.XMATCH(EDM自动!$B$12,$BW$1:$BW$108,-1)),1),"00"))} -> 03 | O8: {=TEXT(IF(AA8=0,"",INDEX(BN5:BN112,_xlfn.XMATCH(EDM自动!$B$12,$BW$1:$BW$108,-1))),"000")} -> 000 | P8: {=TEXT(IF(AA8=0,"",INDEX(BO5:BO112,_xlfn.XMATCH(EDM自动!$B$12,$BW$1:$BW$108,-1))),"00")} -> 10 | Q8: {=IF(AA8=0,"",INDEX(BP5:BP112,_xlfn.XMATCH(EDM自动!$B$12,$BW$1:$BW$108,-1)))} -> 3 | R8: {=IF(AA8=0,"",INDEX(BL5:BL112,_xlfn.XMATCH(EDM自动!$B$12,$BW$1:$BW$108,-1)))} -> 73 | S8: {=TEXT(IF(AA8=0,"",INDEX(BT5:BT112,_xlfn.XMATCH(EDM自动!$B$12,$BW$1:$BW$108,-1))),"00")} -> 05 | T8: {=TEXT(IF(AA8=0,"",INDEX(BS5:BS112,_xlfn.XMATCH(EDM自动!$B$12,$BW$1:$BW$108,-1))),"00")} -> 30 | U8: {=TEXT(IF(AA8=0,"",INDEX(BJ5:BJ112,_xlfn.XMATCH(EDM自动!$B$12,$BW$1:$BW$108,-1))),"000")} -> 180 | V8: {=TEXT(IF(AA8=0,"",INDEX(BK5:BK112,_xlfn.XMATCH(EDM自动!$B$12,$BW$1:$BW$108,-1))),"00")} -> 00 | W8: {=TEXT(IF(AA8=0,"",INDEX(BM5:BM112,_xlfn.XMATCH(EDM自动!$B$12,$BW$1:$BW$108,-1))),"0000")} -> 0000 | X8: {=TEXT(IF(AA8=0,"",INDEX(BU5:BU112,_xlfn.XMATCH(EDM自动!$B$12,$BW$1:$BW$108,-1))),"0000")} -> 3202 | Y8: =IF(AA8=0,"",";") -> ; | Z8: {=INDEX(BV5:BV112,_xlfn.XMATCH(EDM自动!$B$12,$BW$1:$BW$108,-1))} -> -0.007 | AA8: {=INDEX(BW5:BW112,_xlfn.XMATCH(EDM自动!$B$12,$BW$1:$BW$108,-1))} -> 0.026 | AB8: {=INDEX(BZ5:BZ112,_xlfn.XMATCH(EDM自动!$B$12,$BW$1:$BW$108,-1))} -> Z | AC8: {=INDEX(CA5:CA112,_xlfn.XMATCH(EDM自动!$B$12,$BW$1:$BW$108,-1))} -> 10400 | BB8: 4 | BC8: 40 | BD8: 20 | BE8: 0 | BF8: 23 | BG8: 70 | BH8: 15 | BI8: 18 | BJ8: 180 | BK8: 00 | BL8: 73 | BM8: 0 | BN8: 40 | BO8: 0 | BP8: 0 | BQ8: + | BR8: 31 | BS8: 15 | BT8: 4 | BU8: 2202 | BV8: 0.052 | BW8: 0.052 | BX8: 24 | BY8: 0 | BZ8: T | CA8: 0 | CB8: 2.8 | CC8: 1 | CD8: 90 | CE8: 1 | CF8: 1 | CG8: 0.63 | CH8: 0
A9: {=IF(AA9=0,"",TEXT(INDEX(BB6:BB113,_xlfn.XMATCH(EDM自动!$B$12,$BW$1:$BW$108,-1)),"C000"))} -> C801 | B9: =IF(AA9=0,"","=") -> = | C9: {=TEXT(IF(AA9=0,"",INDEX(BC6:BC113,_xlfn.XMATCH(EDM自动!$B$12,$BW$1:$BW$108,-1))),"0000")} -> 0001 | D9: {=TEXT(IF(AA9=0,"",INDEX(BD6:BD113,_xlfn.XMATCH(EDM自动!$B$12,$BW$1:$BW$108,-1))),"0000")} -> 0009 | E9: {=TEXT(IF(AA9=0,"",INDEX(BE6:BE113,_xlfn.XMATCH(EDM自动!$B$12,$BW$1:$BW$108,-1))),"0000")} -> 0000 | F9: {=TEXT(IF(AA9=0,"",INDEX(BF6:BF113,_xlfn.XMATCH(EDM自动!$B$12,$BW$1:$BW$108,-1))),"0000")} -> 0015 | G9: {=TEXT(IF(AA9=0,"",INDEX(BG6:BG113,_xlfn.XMATCH(EDM自动!$B$12,$BW$1:$BW$108,-1))),"000")} -> 110 | H9: {=TEXT(IF(AA9=0,"",INDEX(BH6:BH113,_xlfn.XMATCH(EDM自动!$B$12,$BW$1:$BW$108,-1))),"000")} -> 015 | I9: {=TEXT(IF(AA9=0,"",INDEX(BI6:BI113,_xlfn.XMATCH(EDM自动!$B$12,$BW$1:$BW$108,-1))),"000")} -> 020 | J9: =TEXT(IF(AA9=0,"",0),"000") -> 000 | K9: =IF(AA9=0,"",IF(A9=0,"",EDM自动!$C$9)) -> LP=1234 | L9: =TEXT(IF(AA9=0,"",0),"0.000") -> 0.000 | M9: {=IF(AA9=0,"",INDEX(BQ6:BQ113,_xlfn.XMATCH(EDM自动!$B$12,$BW$1:$BW$108,-1)))} -> - | N9: {=IF(AA9=0,"",TEXT(LEFT(INDEX(BR6:BR113,_xlfn.XMATCH(EDM自动!$B$12,$BW$1:$BW$108,-1)),1),"00"))} -> 03 | O9: {=TEXT(IF(AA9=0,"",INDEX(BN6:BN113,_xlfn.XMATCH(EDM自动!$B$12,$BW$1:$BW$108,-1))),"000")} -> 000 | P9: {=TEXT(IF(AA9=0,"",INDEX(BO6:BO113,_xlfn.XMATCH(EDM自动!$B$12,$BW$1:$BW$108,-1))),"00")} -> 10 | Q9: {=IF(AA9=0,"",INDEX(BP6:BP113,_xlfn.XMATCH(EDM自动!$B$12,$BW$1:$BW$108,-1)))} -> 3 | R9: {=IF(AA9=0,"",INDEX(BL6:BL113,_xlfn.XMATCH(EDM自动!$B$12,$BW$1:$BW$108,-1)))} -> 73 | S9: {=TEXT(IF(AA9=0,"",INDEX(BT6:BT113,_xlfn.XMATCH(EDM自动!$B$12,$BW$1:$BW$108,-1))),"00")} -> 05 | T9: {=TEXT(IF(AA9=0,"",INDEX(BS6:BS113,_xlfn.XMATCH(EDM自动!$B$12,$BW$1:$BW$108,-1))),"00")} -> 30 | U9: {=TEXT(IF(AA9=0,"",INDEX(BJ6:BJ113,_xlfn.XMATCH(EDM自动!$B$12,$BW$1:$BW$108,-1))),"000")} -> 180 | V9: {=TEXT(IF(AA9=0,"",INDEX(BK6:BK113,_xlfn.XMATCH(EDM自动!$B$12,$BW$1:$BW$108,-1))),"00")} -> 00 | W9: {=TEXT(IF(AA9=0,"",INDEX(BM6:BM113,_xlfn.XMATCH(EDM自动!$B$12,$BW$1:$BW$108,-1))),"0000")} -> 0000 | X9: {=TEXT(IF(AA9=0,"",INDEX(BU6:BU113,_xlfn.XMATCH(EDM自动!$B$12,$BW$1:$BW$108,-1))),"0000")} -> 3202 | Y9: =IF(AA9=0,"",";") -> ; | Z9: {=INDEX(BV6:BV113,_xlfn.XMATCH(EDM自动!$B$12,$BW$1:$BW$108,-1))} -> 0.013 | AA9: {=INDEX(BW6:BW113,_xlfn.XMATCH(EDM自动!$B$12,$BW$1:$BW$108,-1))} -> 0.011 | AB9: {=INDEX(BZ6:BZ113,_xlfn.XMATCH(EDM自动!$B$12,$BW$1:$BW$108,-1))} -> Z | AC9: {=INDEX(CA6:CA113,_xlfn.XMATCH(EDM自动!$B$12,$BW$1:$BW$108,-1))} -> 312 | BB9: 3 | BC9: 10 | BD9: 9 | BE9: 0 | BF9: 15 | BG9: 80 | BH9: 15 | BI9: 18 | BJ9: 180 | BK9: 00 | BL9: 73 | BM9: 0 | BN9: 40 | BO9: 0 | BP9: 0 | BQ9: + | BR9: 31 | BS9: 15 | BT9: 5 | BU9: 2202 | BV9: 0.03 | BW9: 0.033 | BX9: 24 | BY9: 0 | BZ9: T | CA9: 0 | CB9: 2 | CC9: 1 | CD9: 90 | CE9: 1 | CF9: 1 | CG9: 0.63 | CH9: 0
A10: {=IF(AA10=0,"",TEXT(INDEX(BB7:BB114,_xlfn.XMATCH(EDM自动!$B$12,$BW$1:$BW$108,-1)),"C000"))} | B10: =IF(AA10=0,"","=") | C10: {=TEXT(IF(AA10=0,"",INDEX(BC7:BC114,_xlfn.XMATCH(EDM自动!$B$12,$BW$1:$BW$108,-1))),"0000")} | D10: {=TEXT(IF(AA10=0,"",INDEX(BD7:BD114,_xlfn.XMATCH(EDM自动!$B$12,$BW$1:$BW$108,-1))),"0000")} | E10: {=TEXT(IF(AA10=0,"",INDEX(BE7:BE114,_xlfn.XMATCH(EDM自动!$B$12,$BW$1:$BW$108,-1))),"0000")} | F10: {=TEXT(IF(AA10=0,"",INDEX(BF7:BF114,_xlfn.XMATCH(EDM自动!$B$12,$BW$1:$BW$108,-1))),"0000")} | G10: {=TEXT(IF(AA10=0,"",INDEX(BG7:BG114,_xlfn.XMATCH(EDM自动!$B$12,$BW$1:$BW$108,-1))),"000")} | H10: {=TEXT(IF(AA10=0,"",INDEX(BH7:BH114,_xlfn.XMATCH(EDM自动!$B$12,$BW$1:$BW$108,-1))),"000")} | I10: {=TEXT(IF(AA10=0,"",INDEX(BI7:BI114,_xlfn.XMATCH(EDM自动!$B$12,$BW$1:$BW$108,-1))),"000")} | J10: =TEXT(IF(AA10=0,"",0),"000") | K10: =IF(AA10=0,"",IF(A10=0,"",EDM自动!$C$9)) | L10: =TEXT(IF(AA10=0,"",0),"0.000") | M10: {=IF(AA10=0,"",INDEX(BQ7:BQ114,_xlfn.XMATCH(EDM自动!$B$12,$BW$1:$BW$108,-1)))} | N10: {=IF(AA10=0,"",TEXT(LEFT(INDEX(BR7:BR114,_xlfn.XMATCH(EDM自动!$B$12,$BW$1:$BW$108,-1)),1),"00"))} | O10: {=TEXT(IF(AA10=0,"",INDEX(BN7:BN114,_xlfn.XMATCH(EDM自动!$B$12,$BW$1:$BW$108,-1))),"000")} | P10: {=TEXT(IF(AA10=0,"",INDEX(BO7:BO114,_xlfn.XMATCH(EDM自动!$B$12,$BW$1:$BW$108,-1))),"00")} | Q10: {=IF(AA10=0,"",INDEX(BP7:BP114,_xlfn.XMATCH(EDM自动!$B$12,$BW$1:$BW$108,-1)))} | R10: {=IF(AA10=0,"",INDEX(BL7:BL114,_xlfn.XMATCH(EDM自动!$B$12,$BW$1:$BW$108,-1)))} | S10: {=TEXT(IF(AA10=0,"",INDEX(BT7:BT114,_xlfn.XMATCH(EDM自动!$B$12,$BW$1:$BW$108,-1))),"00")} | T10: {=TEXT(IF(AA10=0,"",INDEX(BS7:BS114,_xlfn.XMATCH(EDM自动!$B$12,$BW$1:$BW$108,-1))),"00")} | U10: {=TEXT(IF(AA10=0,"",INDEX(BJ7:BJ114,_xlfn.XMATCH(EDM自动!$B$12,$BW$1:$BW$108,-1))),"000")} | V10: {=TEXT(IF(AA10=0,"",INDEX(BK7:BK114,_xlfn.XMATCH(EDM自动!$B$12,$BW$1:$BW$108,-1))),"00")} | W10: {=TEXT(IF(AA10=0,"",INDEX(BM7:BM114,_xlfn.XMATCH(EDM自动!$B$12,$BW$1:$BW$108,-1))),"0000")} | X10: {=TEXT(IF(AA10=0,"",INDEX(BU7:BU114,_xlfn.XMATCH(EDM自动!$B$12,$BW$1:$BW$108,-1))),"0000")} | Y10: =IF(AA10=0,"",";") | Z10: {=INDEX(BV7:BV114,_xlfn.XMATCH(EDM自动!$B$12,$BW$1:$BW$108,-1))} -> 0 | AA10: {=INDEX(BW7:BW114,_xlfn.XMATCH(EDM自动!$B$12,$BW$1:$BW$108,-1))} -> 0 | AB10: {=INDEX(BZ7:BZ114,_xlfn.XMATCH(EDM自动!$B$12,$BW$1:$BW$108,-1))} -> 0 | AC10: {=INDEX(CA7:CA114,_xlfn.XMATCH(EDM自动!$B$12,$BW$1:$BW$108,-1))} -> 0 | BB10: 2 | BC10: 7 | BD10: 9 | BE10: 0 | BF10: 8 | BG10: 95 | BH10: 15 | BI10: 20 | BJ10: 180 | BK10: 00 | BL10: 73 | BM10: 0 | BN10: 0 | BO10: 0 | BP10: 0 | BQ10: + | BR10: 31 | BS10: 15 | BT10: 5 | BU10: 2202 | BV10: 0.018 | BW10: 0.023 | BX10: 24 | BY10: 0 | BZ10: T | CA10: 0 | CB10: 1.12 | CC10: 1 | CD10: 90 | CE10: 1 | CF10: 1 | CG10: 0.63 | CH10: 0
A11: {=IF(AA11=0,"",TEXT(INDEX(BB8:BB115,_xlfn.XMATCH(EDM自动!$B$12,$BW$1:$BW$108,-1)),"C000"))} | B11: =IF(AA11=0,"","=") | C11: {=TEXT(IF(AA11=0,"",INDEX(BC8:BC115,_xlfn.XMATCH(EDM自动!$B$12,$BW$1:$BW$108,-1))),"0000")} | D11: {=TEXT(IF(AA11=0,"",INDEX(BD8:BD115,_xlfn.XMATCH(EDM自动!$B$12,$BW$1:$BW$108,-1))),"0000")} | E11: {=TEXT(IF(AA11=0,"",INDEX(BE8:BE115,_xlfn.XMATCH(EDM自动!$B$12,$BW$1:$BW$108,-1))),"0000")} | F11: {=TEXT(IF(AA11=0,"",INDEX(BF8:BF115,_xlfn.XMATCH(EDM自动!$B$12,$BW$1:$BW$108,-1))),"0000")} | G11: {=TEXT(IF(AA11=0,"",INDEX(BG8:BG115,_xlfn.XMATCH(EDM自动!$B$12,$BW$1:$BW$108,-1))),"000")} | H11: {=TEXT(IF(AA11=0,"",INDEX(BH8:BH115,_xlfn.XMATCH(EDM自动!$B$12,$BW$1:$BW$108,-1))),"000")} | I11: {=TEXT(IF(AA11=0,"",INDEX(BI8:BI115,_xlfn.XMATCH(EDM自动!$B$12,$BW$1:$BW$108,-1))),"000")} | J11: =TEXT(IF(AA11=0,"",0),"000") | K11: =IF(AA11=0,"",IF(A11=0,"",EDM自动!$C$9)) | L11: =TEXT(IF(AA11=0,"",0),"0.000") | M11: {=IF(AA11=0,"",INDEX(BQ8:BQ115,_xlfn.XMATCH(EDM自动!$B$12,$BW$1:$BW$108,-1)))} | N11: {=IF(AA11=0,"",TEXT(LEFT(INDEX(BR8:BR115,_xlfn.XMATCH(EDM自动!$B$12,$BW$1:$BW$108,-1)),1),"00"))} | O11: {=TEXT(IF(AA11=0,"",INDEX(BN8:BN115,_xlfn.XMATCH(EDM自动!$B$12,$BW$1:$BW$108,-1))),"000")} | P11: {=TEXT(IF(AA11=0,"",INDEX(BO8:BO115,_xlfn.XMATCH(EDM自动!$B$12,$BW$1:$BW$108,-1))),"00")} | Q11: {=IF(AA11=0,"",INDEX(BP8:BP115,_xlfn.XMATCH(EDM自动!$B$12,$BW$1:$BW$108,-1)))} | R11: {=IF(AA11=0,"",INDEX(BL8:BL115,_xlfn.XMATCH(EDM自动!$B$12,$BW$1:$BW$108,-1)))} | S11: {=TEXT(IF(AA11=0,"",INDEX(BT8:BT115,_xlfn.XMATCH(EDM自动!$B$12,$BW$1:$BW$108,-1))),"00")} | T11: {=TEXT(IF(AA11=0,"",INDEX(BS8:BS115,_xlfn.XMATCH(EDM自动!$B$12,$BW$1:$BW$108,-1))),"00")} | U11: {=TEXT(IF(AA11=0,"",INDEX(BJ8:BJ115,_xlfn.XMATCH(EDM自动!$B$12,$BW$1:$BW$108,-1))),"000")} | V11: {=TEXT(IF(AA11=0,"",INDEX(BK8:BK115,_xlfn.XMATCH(EDM自动!$B$12,$BW$1:$BW$108,-1))),"00")} | W11: {=TEXT(IF(AA11=0,"",INDEX(BM8:BM115,_xlfn.XMATCH(EDM自动!$B$12,$BW$1:$BW$108,-1))),"0000")} | X11: {=TEXT(IF(AA11=0,"",INDEX(BU8:BU115,_xlfn.XMATCH(EDM自动!$B$12,$BW$1:$BW$108,-1))),"0000")} | Y11: =IF(AA11=0,"",";") | Z11: {=INDEX(BV8:BV115,_xlfn.XMATCH(EDM自动!$B$12,$BW$1:$BW$108,-1))} -> 0 | AA11: {=INDEX(BW8:BW115,_xlfn.XMATCH(EDM自动!$B$12,$BW$1:$BW$108,-1))} -> 0 | AB11: {=INDEX(BZ8:BZ115,_xlfn.XMATCH(EDM自动!$B$12,$BW$1:$BW$108,-1))} -> 0 | AC11: {=INDEX(CA8:CA115,_xlfn.XMATCH(EDM自动!$B$12,$BW$1:$BW$108,-1))} -> 0 | BB11: 801 | BC11: 1 | BD11: 9 | BE11: 0 | BF11: 15 | BG11: 110 | BH11: 15 | BI11: 20 | BJ11: 180 | BK11: 00 | BL11: 73 | BM11: 0 | BN11: 0 | BO11: 10 | BP11: 3 | BQ11: - | BR11: 32 | BS11: 30 | BT11: 5 | BU11: 3202 | BV11: -0.007 | BW11: 0.026 | BX11: 24 | BY11: 0.6 | BZ11: Z | CA11: 10400 | CB11: 0.63 | CC11: 1 | CD11: 90 | CE11: 1 | CF11: 1 | CG11: 0.63 | CH11: 0
A12: {=IF(AA12=0,"",TEXT(INDEX(BB9:BB116,_xlfn.XMATCH(EDM自动!$B$12,$BW$1:$BW$108,-1)),"C000"))} | B12: =IF(AA12=0,"","=") | C12: {=TEXT(IF(AA12=0,"",INDEX(BC9:BC116,_xlfn.XMATCH(EDM自动!$B$12,$BW$1:$BW$108,-1))),"0000")} | D12: {=TEXT(IF(AA12=0,"",INDEX(BD9:BD116,_xlfn.XMATCH(EDM自动!$B$12,$BW$1:$BW$108,-1))),"0000")} | E12: {=TEXT(IF(AA12=0,"",INDEX(BE9:BE116,_xlfn.XMATCH(EDM自动!$B$12,$BW$1:$BW$108,-1))),"0000")} | F12: {=TEXT(IF(AA12=0,"",INDEX(BF9:BF116,_xlfn.XMATCH(EDM自动!$B$12,$BW$1:$BW$108,-1))),"0000")} | G12: {=TEXT(IF(AA12=0,"",INDEX(BG9:BG116,_xlfn.XMATCH(EDM自动!$B$12,$BW$1:$BW$108,-1))),"000")} | H12: {=TEXT(IF(AA12=0,"",INDEX(BH9:BH116,_xlfn.XMATCH(EDM自动!$B$12,$BW$1:$BW$108,-1))),"000")} | I12: {=TEXT(IF(AA12=0,"",INDEX(BI9:BI116,_xlfn.XMATCH(EDM自动!$B$12,$BW$1:$BW$108,-1))),"000")} | J12: =TEXT(IF(AA12=0,"",0),"000") | K12: =IF(AA12=0,"",IF(A12=0,"",EDM自动!$C$9)) | L12: =TEXT(IF(AA12=0,"",0),"0.000") | M12: {=IF(AA12=0,"",INDEX(BQ9:BQ116,_xlfn.XMATCH(EDM自动!$B$12,$BW$1:$BW$108,-1)))} | N12: {=IF(AA12=0,"",TEXT(LEFT(INDEX(BR9:BR116,_xlfn.XMATCH(EDM自动!$B$12,$BW$1:$BW$108,-1)),1),"00"))} | O12: {=TEXT(IF(AA12=0,"",INDEX(BN9:BN116,_xlfn.XMATCH(EDM自动!$B$12,$BW$1:$BW$108,-1))),"000")} | P12: {=TEXT(IF(AA12=0,"",INDEX(BO9:BO116,_xlfn.XMATCH(EDM自动!$B$12,$BW$1:$BW$108,-1))),"00")} | Q12: {=IF(AA12=0,"",INDEX(BP9:BP116,_xlfn.XMATCH(EDM自动!$B$12,$BW$1:$BW$108,-1)))} | R12: {=IF(AA12=0,"",INDEX(BL9:BL116,_xlfn.XMATCH(EDM自动!$B$12,$BW$1:$BW$108,-1)))} | S12: {=TEXT(IF(AA12=0,"",INDEX(BT9:BT116,_xlfn.XMATCH(EDM自动!$B$12,$BW$1:$BW$108,-1))),"00")} | T12: {=TEXT(IF(AA12=0,"",INDEX(BS9:BS116,_xlfn.XMATCH(EDM自动!$B$12,$BW$1:$BW$108,-1))),"00")} | U12: {=TEXT(IF(AA12=0,"",INDEX(BJ9:BJ116,_xlfn.XMATCH(EDM自动!$B$12,$BW$1:$BW$108,-1))),"000")} | V12: {=TEXT(IF(AA12=0,"",INDEX(BK9:BK116,_xlfn.XMATCH(EDM自动!$B$12,$BW$1:$BW$108,-1))),"00")} | W12: {=TEXT(IF(AA12=0,"",INDEX(BM9:BM116,_xlfn.XMATCH(EDM自动!$B$12,$BW$1:$BW$108,-1))),"0000")} | X12: {=TEXT(IF(AA12=0,"",INDEX(BU9:BU116,_xlfn.XMATCH(EDM自动!$B$12,$BW$1:$BW$108,-1))),"0000")} | Y12: =IF(AA12=0,"",";") | Z12: {=INDEX(BV9:BV116,_xlfn.XMATCH(EDM自动!$B$12,$BW$1:$BW$108,-1))} -> 0 | AA12: {=INDEX(BW9:BW116,_xlfn.XMATCH(EDM自动!$B$12,$BW$1:$BW$108,-1))} -> 0 | AB12: {=INDEX(BZ9:BZ116,_xlfn.XMATCH(EDM自动!$B$12,$BW$1:$BW$108,-1))} -> 0 | AC12: {=INDEX(CA9:CA116,_xlfn.XMATCH(EDM自动!$B$12,$BW$1:$BW$108,-1))} -> 0 | BB12: 801 | BC12: 1 | BD12: 9 | BE12: 0 | BF12: 15 | BG12: 110 | BH12: 15 | BI12: 20 | BJ12: 180 | BK12: 00 | BL12: 73 | BM12: 0 | BN12: 0 | BO12: 10 | BP12: 3 | BQ12: - | BR12: 32 | BS12: 30 | BT12: 5 | BU12: 3202 | BV12: 0.013 | BW12: 0.011 | BX12: 24 | BY12: 0.6 | BZ12: Z | CA12: 312 | CB12: 0.63 | CC12: 1 | CD12: 90 | CE12: 1 | CF12: 1 | CG12: 0.63 | CH12: 0
